Workbook

Sheet Gesamtübersicht
A1: Team | B1: Startelf-Altersdurchschnitt Saison
A2: Liefering | B2: =Liefering!N1 -> 19.561129
A3: Altach | B3: ='Altach Juniors'!N1 -> 19.690909
A4: Rapid | B4: =Rapid!N1 -> 19.708464
A5: JWR | B5: =JWR!N1 -> 19.83165
A6: LASK | B6: =LASK!N1 -> 20.144781
A7: Sturm | B7: =Sturm!N1 -> 20.806061
A8: WAC | B8: =WAC!N1 -> 20.98951
A9: Young Violets | B9: ='Young Violets'!N1 -> 21.169279

Sheet Alter pro Spieltag
B1: 1. Spieltag | C1: 2. Spieltag | D1: 3. Spieltag | E1: 4. Spieltag | F1: 5. Spieltag | G1: 6. Spieltag | H1: 7. Spieltag | I1: 8. Spieltag | J1: 9. Spieltag | K1: 10. Spieltag | L1: 11. Spieltag | M1: 12. Spieltag | N1: 13. Spieltag | O1: 14. Spieltag | P1: 15. Spieltag | Q1: 16. Spieltag | R1: 17. Spieltag | S1: 18. Spieltag | T1: 19. Spieltag | U1: 20. Spieltag | V1: 21. Spieltag | W1: 22. Spieltag | X1: 23. Spieltag | Y1: 24. Spieltag | Z1: 25. Spieltag | AA1: 26. Spieltag | AB1: 27. Spieltag | AC1: 28. Spieltag | AD1: 29. Spieltag | AE1: 30. Spieltag
A2: JWR | B2: {=INDIRECT("JWR!N" & (COLUMN()-1)*3)} -> 19.727273 | C2: {=INDIRECT("JWR!N" & (COLUMN()-1)*3)} -> 18.727273 | D2: {=INDIRECT("JWR!N" & (COLUMN()-1)*3)} -> 21.272727 | E2: {=INDIRECT("JWR!N" & (COLUMN()-1)*3)} -> 20 | F2: {=INDIRECT("JWR!N" & (COLUMN()-1)*3)} -> 20.909091 | G2: {=INDIRECT("JWR!N" & (COLUMN()-1)*3)} -> 19.090909 | H2: {=INDIRECT("JWR!N" & (COLUMN()-1)*3)} -> 18.727273 | I2: {=INDIRECT("JWR!N" & (COLUMN()-1)*3)} -> 19.727273 | ... AE2: {=INDIRECT("JWR!N" & (COLUMN()-1)*3)} -> 0
A3: LASK | B3: {=INDIRECT("LASK!N" & (COLUMN()-1)*3)} -> 20.545455 | C3: {=INDIRECT("LASK!N" & (COLUMN()-1)*3)} -> 20.818182 | D3: {=INDIRECT("LASK!N" & (COLUMN()-1)*3)} -> 20.545455 | E3: {=INDIRECT("LASK!N" & (COLUMN()-1)*3)} -> 20.090909 | F3: {=INDIRECT("LASK!N" & (COLUMN()-1)*3)} -> 20.363636 | G3: {=INDIRECT("LASK!N" & (COLUMN()-1)*3)} -> 20.454545 | H3: {=INDIRECT("LASK!N" & (COLUMN()-1)*3)} -> 20.545455 | I3: {=INDIRECT("LASK!N" & (COLUMN()-1)*3)} -> 20.545455 | ... AE3: {=INDIRECT("LASK!N" & (COLUMN()-1)*3)} -> 0
A4: Altach Juniors | B4: {=INDIRECT("'Altach Juniors'!N" & (COLUMN()-1)*3)} -> 19.181818 | C4: {=INDIRECT("'Altach Juniors'!N" & (COLUMN()-1)*3)} -> 19.727273 | D4: {=INDIRECT("'Altach Juniors'!N" & (COLUMN()-1)*3)} -> 19.363636 | E4: {=INDIRECT("'Altach Juniors'!N" & (COLUMN()-1)*3)} -> 19.727273 | F4: {=INDIRECT("'Altach Juniors'!N" & (COLUMN()-1)*3)} -> 19.818182 | G4: {=INDIRECT("'Altach Juniors'!N" & (COLUMN()-1)*3)} -> 19.545455 | H4: {=INDIRECT("'Altach Juniors'!N" & (COLUMN()-1)*3)} -> 20.454545 | I4: {=INDIRECT("'Altach Juniors'!N" & (COLUMN()-1)*3)} -> 19.545455 | ... AE4: {=INDIRECT("'Altach Juniors'!N" & (COLUMN()-1)*3)} -> 0
A5: Young Violets | B5: {=INDIRECT("'Young Violets'!N" & (COLUMN()-1)*3)} -> 20.818182 | C5: {=INDIRECT("'Young Violets'!N" & (COLUMN()-1)*3)} -> 20.909091 | D5: {=INDIRECT("'Young Violets'!N" & (COLUMN()-1)*3)} -> 21.090909 | E5: {=INDIRECT("'Young Violets'!N" & (COLUMN()-1)*3)} -> 21.181818 | F5: {=INDIRECT("'Young Violets'!N" & (COLUMN()-1)*3)} -> 21.363636 | G5: {=INDIRECT("'Young Violets'!N" & (COLUMN()-1)*3)} -> 21.272727 | H5: {=INDIRECT("'Young Violets'!N" & (COLUMN()-1)*3)} -> 21.363636 | I5: {=INDIRECT("'Young Violets'!N" & (COLUMN()-1)*3)} -> 20.909091 | ... AE5: {=INDIRECT("'Young Violets'!N" & (COLUMN()-1)*3)} -> 0
A6: WAC | B6: {=INDIRECT("WAC!N" & (COLUMN()-1)*3)} -> 21.272727 | C6: {=INDIRECT("WAC!N" & (COLUMN()-1)*3)} -> 21.545455 | D6: {=INDIRECT("WAC!N" & (COLUMN()-1)*3)} -> 21.272727 | E6: {=INDIRECT("WAC!N" & (COLUMN()-1)*3)} -> 21.181818 | F6: {=INDIRECT("WAC!N" & (COLUMN()-1)*3)} -> 21 | G6: {=INDIRECT("WAC!N" & (COLUMN()-1)*3)} -> 20.363636 | H6: {=INDIRECT("WAC!N" & (COLUMN()-1)*3)} -> 20.454545 | I6: {=INDIRECT("WAC!N" & (COLUMN()-1)*3)} -> 20.727273 | ... AE6: {=INDIRECT("WAC!N" & (COLUMN()-1)*3)} -> 0
A7: Rapid | B7: {=INDIRECT("Rapid!N" & (COLUMN()-1)*3)} -> 20 | C7: {=INDIRECT("Rapid!N" & (COLUMN()-1)*3)} -> 20.454545 | D7: {=INDIRECT("Rapid!N" & (COLUMN()-1)*3)} -> 20.454545 | E7: {=INDIRECT("Rapid!N" & (COLUMN()-1)*3)} -> 20.272727 | F7: {=INDIRECT("Rapid!N" & (COLUMN()-1)*3)} -> 20.272727 | G7: {=INDIRECT("Rapid!N" & (COLUMN()-1)*3)} -> 20.363636 | H7: {=INDIRECT("Rapid!N" & (COLUMN()-1)*3)} -> 19.909091 | I7: {=INDIRECT("Rapid!N" & (COLUMN()-1)*3)} -> 20 | ... AE7: {=INDIRECT("Rapid!N" & (COLUMN()-1)*3)} -> 0
A8: Liefering | B8: {=INDIRECT("Liefering!N" & (COLUMN()-1)*3)} -> 19.454545 | C8: {=INDIRECT("Liefering!N" & (COLUMN()-1)*3)} -> 19.636364 | D8: {=INDIRECT("Liefering!N" & (COLUMN()-1)*3)} -> 19.727273 | E8: {=INDIRECT("Liefering!N" & (COLUMN()-1)*3)} -> 19.636364 | F8: {=INDIRECT("Liefering!N" & (COLUMN()-1)*3)} -> 19.636364 | G8: {=INDIRECT("Liefering!N" & (COLUMN()-1)*3)} -> 19.636364 | H8: {=INDIRECT("Liefering!N" & (COLUMN()-1)*3)} -> 19.545455 | I8: {=INDIRECT("Liefering!N" & (COLUMN()-1)*3)} -> 19.636364 | ... AE8: {=INDIRECT("Liefering!N" & (COLUMN()-1)*3)} -> 0
A9: Sturm | B9: {=INDIRECT("Sturm!N" & (COLUMN()-1)*3)} -> 20.272727 | C9: {=INDIRECT("Sturm!N" & (COLUMN()-1)*3)} -> 20.545455 | D9: {=INDIRECT("Sturm!N" & (COLUMN()-1)*3)} -> 20.454545 | E9: {=INDIRECT("Sturm!N" & (COLUMN()-1)*3)} -> 20.545455 | F9: {=INDIRECT("Sturm!N" & (COLUMN()-1)*3)} -> 20.181818 | G9: {=INDIRECT("Sturm!N" & (COLUMN()-1)*3)} -> 20.363636 | H9: {=INDIRECT("Sturm!N" & (COLUMN()-1)*3)} -> 21.363636 | I9: {=INDIRECT("Sturm!N" & (COLUMN()-1)*3)} -> 21 | ... AE9: {=INDIRECT("Sturm!N" & (COLUMN()-1)*3)} -> 20.181818

Sheet JWR
N1: =AVERAGE(N3:N99) -> 19.83165
A2: LASK | B2: Wimmer F. | C2: Ablinger | D2: Weissenbacher | E2: Nezic | F2: Scholl | G2: Balabas | H2: Bogou | I2: Zotz | J2: Forobosko | K2: Arencibia | L2: Olinga
B3: =DATEDIF(VLOOKUP(B2,$P$18:$Q$100,2,FALSE),TODAY(),"Y") -> 27 | C3: =DATEDIF(VLOOKUP(C2,$P$18:$Q$100,2,FALSE),TODAY(),"Y") -> 18 | D3: =DATEDIF(VLOOKUP(D2,$P$18:$Q$100,2,FALSE),TODAY(),"Y") -> 20 | E3: =DATEDIF(VLOOKUP(E2,$P$18:$Q$100,2,FALSE),TODAY(),"Y") -> 19 | F3: =DATEDIF(VLOOKUP(F2,$P$18:$Q$100,2,FALSE),TODAY(),"Y") -> 18 | G3: =DATEDIF(VLOOKUP(G2,$P$18:$Q$100,2,FALSE),TODAY(),"Y") -> 19 | H3: =DATEDIF(VLOOKUP(H2,$P$18:$Q$100,2,FALSE),TODAY(),"Y") -> 18 | I3: =DATEDIF(VLOOKUP(I2,$P$18:$Q$100,2,FALSE),TODAY(),"Y") -> 18 | ... L3: =DATEDIF(VLOOKUP(L2,$P$18:$Q$100,2,FALSE),TODAY(),"Y") -> 21 | N3: =AVERAGE(B3:M3) -> 19.727273
A5: Dietach | B5: Frey | C5: Ablinger | D5: Weissenbacher | E5: Nezic | F5: Scholl | G5: Krain | H5: Abubakar | I5: Zotz | J5: Forobosko | K5: Koplarovics | L5: Olinga
B6: =DATEDIF(VLOOKUP(B5,$P$18:$Q$100,2,FALSE),TODAY(),"Y") -> 17 | C6: =DATEDIF(VLOOKUP(C5,$P$18:$Q$100,2,FALSE),TODAY(),"Y") -> 18 | D6: =DATEDIF(VLOOKUP(D5,$P$18:$Q$100,2,FALSE),TODAY(),"Y") -> 20 | E6: =DATEDIF(VLOOKUP(E5,$P$18:$Q$100,2,FALSE),TODAY(),"Y") -> 19 | F6: =DATEDIF(VLOOKUP(F5,$P$18:$Q$100,2,FALSE),TODAY(),"Y") -> 18 | G6: =DATEDIF(VLOOKUP(G5,$P$18:$Q$100,2,FALSE),TODAY(),"Y") -> 17 | H6: =DATEDIF(VLOOKUP(H5,$P$18:$Q$100,2,FALSE),TODAY(),"Y") -> 21 | I6: =DATEDIF(VLOOKUP(I5,$P$18:$Q$100,2,FALSE),TODAY(),"Y") -> 18 | ... L6: =DATEDIF(VLOOKUP(L5,$P$18:$Q$100,2,FALSE),TODAY(),"Y") -> 21 | N6: =AVERAGE(B6:M6) -> 18.727273
A8: WAC | B8: Wimmer F. | C8: Ablinger | D8: Weissenbacher | E8: Nezic | F8: Scholl | G8: Rossdorfer | H8: Bogou | I8: Abubakar | J8: Forobosko | K8: Sane | L8: Olinga
B9: =DATEDIF(VLOOKUP(B8,$P$18:$Q$100,2,FALSE),TODAY(),"Y") -> 27 | C9: =DATEDIF(VLOOKUP(C8,$P$18:$Q$100,2,FALSE),TODAY(),"Y") -> 18 | D9: =DATEDIF(VLOOKUP(D8,$P$18:$Q$100,2,FALSE),TODAY(),"Y") -> 20 | E9: =DATEDIF(VLOOKUP(E8,$P$18:$Q$100,2,FALSE),TODAY(),"Y") -> 19 | F9: =DATEDIF(VLOOKUP(F8,$P$18:$Q$100,2,FALSE),TODAY(),"Y") -> 18 | G9: =DATEDIF(VLOOKUP(G8,$P$18:$Q$100,2,FALSE),TODAY(),"Y") -> 20 | H9: =DATEDIF(VLOOKUP(H8,$P$18:$Q$100,2,FALSE),TODAY(),"Y") -> 18 | I9: =DATEDIF(VLOOKUP(I8,$P$18:$Q$100,2,FALSE),TODAY(),"Y") -> 21 | ... L9: =DATEDIF(VLOOKUP(L8,$P$18:$Q$100,2,FALSE),TODAY(),"Y") -> 21 | N9: =AVERAGE(B9:M9) -> 21.272727
A11: Voitsberg | B11: Frey | C11: Ablinger | D11: Weissenbacher | E11: Nezic | F11: Scholl | G11: Richards | H11: Zotz | I11: Balabas | J11: Forobosko | K11: Sane | L11: Olinga
B12: =DATEDIF(VLOOKUP(B11,$P$18:$Q$100,2,FALSE),TODAY(),"Y") -> 17 | C12: =DATEDIF(VLOOKUP(C11,$P$18:$Q$100,2,FALSE),TODAY(),"Y") -> 18 | D12: =DATEDIF(VLOOKUP(D11,$P$18:$Q$100,2,FALSE),TODAY(),"Y") -> 20 | E12: =DATEDIF(VLOOKUP(E11,$P$18:$Q$100,2,FALSE),TODAY(),"Y") -> 19 | F12: =DATEDIF(VLOOKUP(F11,$P$18:$Q$100,2,FALSE),TODAY(),"Y") -> 18 | G12: =DATEDIF(VLOOKUP(G11,$P$18:$Q$100,2,FALSE),TODAY(),"Y") -> 18 | H12: =DATEDIF(VLOOKUP(H11,$P$18:$Q$100,2,FALSE),TODAY(),"Y") -> 18 | I12: =DATEDIF(VLOOKUP(I11,$P$18:$Q$100,2,FALSE),TODAY(),"Y") -> 19 | ... L12: =DATEDIF(VLOOKUP(L11,$P$18:$Q$100,2,FALSE),TODAY(),"Y") -> 21 | N12: =AVERAGE(B12:M12) -> 20
A14: St. Anna | B14: Wimmer F. | C14: Ablinger | D14: Weissenbacher | E14: Nezic | F14: Scholl | G14: Balabas | H14: Bogou | I14: Zotz | J14: Forobosko | K14: Sane | L14: Olinga
B15: =DATEDIF(VLOOKUP(B14,$P$18:$Q$100,2,FALSE),TODAY(),"Y") -> 27 | C15: =DATEDIF(VLOOKUP(C14,$P$18:$Q$100,2,FALSE),TODAY(),"Y") -> 18 | D15: =DATEDIF(VLOOKUP(D14,$P$18:$Q$100,2,FALSE),TODAY(),"Y") -> 20 | E15: =DATEDIF(VLOOKUP(E14,$P$18:$Q$100,2,FALSE),TODAY(),"Y") -> 19 | F15: =DATEDIF(VLOOKUP(F14,$P$18:$Q$100,2,FALSE),TODAY(),"Y") -> 18 | G15: =DATEDIF(VLOOKUP(G14,$P$18:$Q$100,2,FALSE),TODAY(),"Y") -> 19 | H15: =DATEDIF(VLOOKUP(H14,$P$18:$Q$100,2,FALSE),TODAY(),"Y") -> 18 | I15: =DATEDIF(VLOOKUP(I14,$P$18:$Q$100,2,FALSE),TODAY(),"Y") -> 18 | ... L15: =DATEDIF(VLOOKUP(L14,$P$18:$Q$100,2,FALSE),TODAY(),"Y") -> 21 | N15: =AVERAGE(B15:M15) -> 20.909091
A17: Treibach | B17: Stöger | C17: Ablinger | D17: Weissenbacher | E17: Spiegl | F17: Scholl | G17: Balabas | H17: Bogou | I17: Rossdorfer | J17: Forobosko | K17: Arencibia | L17: Olinga
B18: =DATEDIF(VLOOKUP(B17,$P$18:$Q$100,2,FALSE),TODAY(),"Y") -> 19 | C18: =DATEDIF(VLOOKUP(C17,$P$18:$Q$100,2,FALSE),TODAY(),"Y") -> 18 | D18: =DATEDIF(VLOOKUP(D17,$P$18:$Q$100,2,FALSE),TODAY(),"Y") -> 20 | E18: =DATEDIF(VLOOKUP(E17,$P$18:$Q$100,2,FALSE),TODAY(),"Y") -> 18 | F18: =DATEDIF(VLOOKUP(F17,$P$18:$Q$100,2,FALSE),TODAY(),"Y") -> 18 | G18: =DATEDIF(VLOOKUP(G17,$P$18:$Q$100,2,FALSE),TODAY(),"Y") -> 19 | H18: =DATEDIF(VLOOKUP(H17,$P$18:$Q$100,2,FALSE),TODAY(),"Y") -> 18 | I18: =DATEDIF(VLOOKUP(I17,$P$18:$Q$100,2,FALSE),TODAY(),"Y") -> 20 | ... L18: =DATEDIF(VLOOKUP(L17,$P$18:$Q$100,2,FALSE),TODAY(),"Y") -> 21 | N18: =AVERAGE(B18:M18) -> 19.090909 | P18: Wimmer F. | Q18: 36024 | T18: 40
P19: Ablinger | Q19: 39233
A20: Kalsdorf | B20: Frey | C20: Ablinger | D20: Balabas | E20: Nezic | F20: Krain | G20: Scholl | H20: Forobosko | I20: Wimmer D. | J20: Abubakar | K20: Arencibia | L20: Spiegl | P20: Nezic | Q20: 39158
B21: =DATEDIF(VLOOKUP(B20,$P$18:$Q$100,2,FALSE),TODAY(),"Y") -> 17 | C21: =DATEDIF(VLOOKUP(C20,$P$18:$Q$100,2,FALSE),TODAY(),"Y") -> 18 | D21: =DATEDIF(VLOOKUP(D20,$P$18:$Q$100,2,FALSE),TODAY(),"Y") -> 19 | E21: =DATEDIF(VLOOKUP(E20,$P$18:$Q$100,2,FALSE),TODAY(),"Y") -> 19 | F21: =DATEDIF(VLOOKUP(F20,$P$18:$Q$100,2,FALSE),TODAY(),"Y") -> 17 | G21: =DATEDIF(VLOOKUP(G20,$P$18:$Q$100,2,FALSE),TODAY(),"Y") -> 18 | H21: =DATEDIF(VLOOKUP(H20,$P$18:$Q$100,2,FALSE),TODAY(),"Y") -> 19 | I21: =DATEDIF(VLOOKUP(I20,$P$18:$Q$100,2,FALSE),TODAY(),"Y") -> 20 | ... L21: =DATEDIF(VLOOKUP(L20,$P$18:$Q$100,2,FALSE),TODAY(),"Y") -> 18 | N21: =AVERAGE(B21:M21) -> 18.727273 | P21: Weissenbacher | Q21: 38504
P22: Forobosko | Q22: 38946
A23: Velden | B23: Wimmer F. | C23: Ablinger | D23: Balabas | E23: Weissenbacher | F23: Krain | G23: Scholl | H23: Olinga | I23: Wimmer D. | J23: Zotz | K23: Arencibia | L23: Leodolter | P23: Balabas | Q23: 38883
B24: =DATEDIF(VLOOKUP(B23,$P$18:$Q$100,2,FALSE),TODAY(),"Y") -> 27 | C24: =DATEDIF(VLOOKUP(C23,$P$18:$Q$100,2,FALSE),TODAY(),"Y") -> 18 | D24: =DATEDIF(VLOOKUP(D23,$P$18:$Q$100,2,FALSE),TODAY(),"Y") -> 19 | E24: =DATEDIF(VLOOKUP(E23,$P$18:$Q$100,2,FALSE),TODAY(),"Y") -> 20 | F24: =DATEDIF(VLOOKUP(F23,$P$18:$Q$100,2,FALSE),TODAY(),"Y") -> 17 | G24: =DATEDIF(VLOOKUP(G23,$P$18:$Q$100,2,FALSE),TODAY(),"Y") -> 18 | H24: =DATEDIF(VLOOKUP(H23,$P$18:$Q$100,2,FALSE),TODAY(),"Y") -> 21 | I24: =DATEDIF(VLOOKUP(I23,$P$18:$Q$100,2,FALSE),TODAY(),"Y") -> 20 | ... L24: =DATEDIF(VLOOKUP(L23,$P$18:$Q$100,2,FALSE),TODAY(),"Y") -> 19 | N24: =AVERAGE(B24:M24) -> 19.727273 | P24: Scholl | Q24: 39290
P25: Zotz | Q25: 39266
A26: Oedt | B26: Frey | C26: Ablinger | D26: Balabas | E26: Weissenbacher | F26: Krain | G26: Scholl | H26: Olinga | I26: Wimmer D. | J26: Zotz | K26: Arencibia | L26: Leodolter | P26: Bogou | Q26: 39372
B27: =DATEDIF(VLOOKUP(B26,$P$18:$Q$100,2,FALSE),TODAY(),"Y") -> 17 | C27: =DATEDIF(VLOOKUP(C26,$P$18:$Q$100,2,FALSE),TODAY(),"Y") -> 18 | D27: =DATEDIF(VLOOKUP(D26,$P$18:$Q$100,2,FALSE),TODAY(),"Y") -> 19 | E27: =DATEDIF(VLOOKUP(E26,$P$18:$Q$100,2,FALSE),TODAY(),"Y") -> 20 | F27: =DATEDIF(VLOOKUP(F26,$P$18:$Q$100,2,FALSE),TODAY(),"Y") -> 17 | G27: =DATEDIF(VLOOKUP(G26,$P$18:$Q$100,2,FALSE),TODAY(),"Y") -> 18 | H27: =DATEDIF(VLOOKUP(H26,$P$18:$Q$100,2,FALSE),TODAY(),"Y") -> 21 | I27: =DATEDIF(VLOOKUP(I26,$P$18:$Q$100,2,FALSE),TODAY(),"Y") -> 20 | ... L27: =DATEDIF(VLOOKUP(L26,$P$18:$Q$100,2,FALSE),TODAY(),"Y") -> 19 | N27: =AVERAGE(B27:M27) -> 18.818182 | P27: Arencibia | Q27: 38668
P28: Olinga | Q28: 38453
A29: Gurten | B29: Wimmer F. | C29: Ablinger | D29: Balabas | E29: Weissenbacher | F29: Krain | G29: Scholl | H29: Olinga | I29: Wimmer D. | J29: Rossdorfer | K29: Bogou | L29: Leodolter | P29: Frey | Q29: 39664
B30: =DATEDIF(VLOOKUP(B29,$P$18:$Q$100,2,FALSE),TODAY(),"Y") -> 27 | C30: =DATEDIF(VLOOKUP(C29,$P$18:$Q$100,2,FALSE),TODAY(),"Y") -> 18 | D30: =DATEDIF(VLOOKUP(D29,$P$18:$Q$100,2,FALSE),TODAY(),"Y") -> 19 | E30: =DATEDIF(VLOOKUP(E29,$P$18:$Q$100,2,FALSE),TODAY(),"Y") -> 20 | F30: =DATEDIF(VLOOKUP(F29,$P$18:$Q$100,2,FALSE),TODAY(),"Y") -> 17 | G30: =DATEDIF(VLOOKUP(G29,$P$18:$Q$100,2,FALSE),TODAY(),"Y") -> 18 | H30: =DATEDIF(VLOOKUP(H29,$P$18:$Q$100,2,FALSE),TODAY(),"Y") -> 21 | I30: =DATEDIF(VLOOKUP(I29,$P$18:$Q$100,2,FALSE),TODAY(),"Y") -> 20 | ... L30: =DATEDIF(VLOOKUP(L29,$P$18:$Q$100,2,FALSE),TODAY(),"Y") -> 19 | N30: =AVERAGE(B30:M30) -> 19.727273 | P30: Krain | Q30: 39653
P31: Koplarovics | Q31: 39418
A32: Wallern | B32: Wimmer F. | C32: Ablinger | D32: Balabas | E32: Spiegl | F32: Krain | G32: Scholl | H32: Olinga | I32: Wimmer D. | J32: Forobosko | K32: Bogou | L32: Leodolter | P32: Abubakar | Q32: 38272
B33: =DATEDIF(VLOOKUP(B32,$P$18:$Q$100,2,FALSE),TODAY(),"Y") -> 27 | C33: =DATEDIF(VLOOKUP(C32,$P$18:$Q$100,2,FALSE),TODAY(),"Y") -> 18 | D33: =DATEDIF(VLOOKUP(D32,$P$18:$Q$100,2,FALSE),TODAY(),"Y") -> 19 | E33: =DATEDIF(VLOOKUP(E32,$P$18:$Q$100,2,FALSE),TODAY(),"Y") -> 18 | F33: =DATEDIF(VLOOKUP(F32,$P$18:$Q$100,2,FALSE),TODAY(),"Y") -> 17 | G33: =DATEDIF(VLOOKUP(G32,$P$18:$Q$100,2,FALSE),TODAY(),"Y") -> 18 | H33: =DATEDIF(VLOOKUP(H32,$P$18:$Q$100,2,FALSE),TODAY(),"Y") -> 21 | I33: =DATEDIF(VLOOKUP(I32,$P$18:$Q$100,2,FALSE),TODAY(),"Y") -> 20 | ... L33: =DATEDIF(VLOOKUP(L32,$P$18:$Q$100,2,FALSE),TODAY(),"Y") -> 19 | N33: =AVERAGE(B33:M33) -> 19.454545 | P33: Rossdorfer | Q33: 38665
P34: Sane | Q34: 33804
A35: Weiz | B35: Wimmer F. | C35: Ablinger | D35: Balabas | E35: Spiegl | F35: Krain | G35: Scholl | H35: Olinga | I35: Wimmer D. | J35: Rossdorfer | K35: Bogou | L35: Leodolter | P35: Richards | Q35: 39356
B36: =DATEDIF(VLOOKUP(B35,$P$18:$Q$100,2,FALSE),TODAY(),"Y") -> 27 | C36: =DATEDIF(VLOOKUP(C35,$P$18:$Q$100,2,FALSE),TODAY(),"Y") -> 18 | D36: =DATEDIF(VLOOKUP(D35,$P$18:$Q$100,2,FALSE),TODAY(),"Y") -> 19 | E36: =DATEDIF(VLOOKUP(E35,$P$18:$Q$100,2,FALSE),TODAY(),"Y") -> 18 | F36: =DATEDIF(VLOOKUP(F35,$P$18:$Q$100,2,FALSE),TODAY(),"Y") -> 17 | G36: =DATEDIF(VLOOKUP(G35,$P$18:$Q$100,2,FALSE),TODAY(),"Y") -> 18 | H36: =DATEDIF(VLOOKUP(H35,$P$18:$Q$100,2,FALSE),TODAY(),"Y") -> 21 | I36: =DATEDIF(VLOOKUP(I35,$P$18:$Q$100,2,FALSE),TODAY(),"Y") -> 20 | ... L36: =DATEDIF(VLOOKUP(L35,$P$18:$Q$100,2,FALSE),TODAY(),"Y") -> 19 | N36: =AVERAGE(B36:M36) -> 19.545455 | P36: Spiegl | Q36: 39361
P37: Stöger | Q37: 38982
A38: DSC | B38: Sturm | C38: Ablinger | D38: Balabas | E38: Abubakar | F38: Kiesl | G38: Scholl | H38: Olinga | I38: Wimmer D. | J38: Zotz | K38: Arencibia | L38: Leodolter | P38: Wimmer D. | Q38: 38539
B39: =DATEDIF(VLOOKUP(B38,$P$18:$Q$100,2,FALSE),TODAY(),"Y") -> 16 | C39: =DATEDIF(VLOOKUP(C38,$P$18:$Q$100,2,FALSE),TODAY(),"Y") -> 18 | D39: =DATEDIF(VLOOKUP(D38,$P$18:$Q$100,2,FALSE),TODAY(),"Y") -> 19 | E39: =DATEDIF(VLOOKUP(E38,$P$18:$Q$100,2,FALSE),TODAY(),"Y") -> 21 | F39: =DATEDIF(VLOOKUP(F38,$P$18:$Q$100,2,FALSE),TODAY(),"Y") -> 18 | G39: =DATEDIF(VLOOKUP(G38,$P$18:$Q$100,2,FALSE),TODAY(),"Y") -> 18 | H39: =DATEDIF(VLOOKUP(H38,$P$18:$Q$100,2,FALSE),TODAY(),"Y") -> 21 | I39: =DATEDIF(VLOOKUP(I38,$P$18:$Q$100,2,FALSE),TODAY(),"Y") -> 20 | ... L39: =DATEDIF(VLOOKUP(L38,$P$18:$Q$100,2,FALSE),TODAY(),"Y") -> 19 | N39: =AVERAGE(B39:M39) -> 18.909091 | P39: Leodolter | Q39: 38932
P40: Sturm | Q40: 39958
A41: Gleisdorf | B41: Wimmer F. | C41: Ablinger | D41: Balabas | E41: Abubakar | F41: Krain | G41: Scholl | H41: Olinga | I41: Wimmer D. | J41: Zotz | K41: Richards | L41: Leodolter | P41: Kiesl | Q41: 39424
B42: =DATEDIF(VLOOKUP(B41,$P$18:$Q$100,2,FALSE),TODAY(),"Y") -> 27 | C42: =DATEDIF(VLOOKUP(C41,$P$18:$Q$100,2,FALSE),TODAY(),"Y") -> 18 | D42: =DATEDIF(VLOOKUP(D41,$P$18:$Q$100,2,FALSE),TODAY(),"Y") -> 19 | E42: =DATEDIF(VLOOKUP(E41,$P$18:$Q$100,2,FALSE),TODAY(),"Y") -> 21 | F42: =DATEDIF(VLOOKUP(F41,$P$18:$Q$100,2,FALSE),TODAY(),"Y") -> 17 | G42: =DATEDIF(VLOOKUP(G41,$P$18:$Q$100,2,FALSE),TODAY(),"Y") -> 18 | H42: =DATEDIF(VLOOKUP(H41,$P$18:$Q$100,2,FALSE),TODAY(),"Y") -> 21 | I42: =DATEDIF(VLOOKUP(I41,$P$18:$Q$100,2,FALSE),TODAY(),"Y") -> 20 | ... L42: =DATEDIF(VLOOKUP(L41,$P$18:$Q$100,2,FALSE),TODAY(),"Y") -> 19 | N42: =AVERAGE(B42:M42) -> 19.636364 | P42: Pesu | Q42: 39739
P43: Danylenko | Q43: 39667
A44: Lafnitz | B44: Frey | C44: Ablinger | D44: Balabas | E44: Abubakar | F44: Krain | G44: Scholl | H44: Olinga | I44: Forobosko | J44: Zotz | K44: Richards | L44: Leodolter | P44: Kirnbauer | Q44: 37496
B45: =DATEDIF(VLOOKUP(B44,$P$18:$Q$100,2,FALSE),TODAY(),"Y") -> 17 | C45: =DATEDIF(VLOOKUP(C44,$P$18:$Q$100,2,FALSE),TODAY(),"Y") -> 18 | D45: =DATEDIF(VLOOKUP(D44,$P$18:$Q$100,2,FALSE),TODAY(),"Y") -> 19 | E45: =DATEDIF(VLOOKUP(E44,$P$18:$Q$100,2,FALSE),TODAY(),"Y") -> 21 | F45: =DATEDIF(VLOOKUP(F44,$P$18:$Q$100,2,FALSE),TODAY(),"Y") -> 17 | G45: =DATEDIF(VLOOKUP(G44,$P$18:$Q$100,2,FALSE),TODAY(),"Y") -> 18 | H45: =DATEDIF(VLOOKUP(H44,$P$18:$Q$100,2,FALSE),TODAY(),"Y") -> 21 | I45: =DATEDIF(VLOOKUP(I44,$P$18:$Q$100,2,FALSE),TODAY(),"Y") -> 19 | ... L45: =DATEDIF(VLOOKUP(L44,$P$18:$Q$100,2,FALSE),TODAY(),"Y") -> 19 | N45: =AVERAGE(B45:M45) -> 18.636364 | P45: Köstenbauer | Q45: 37129
...

Sheet LASK
N1: =AVERAGE(N3:N99) -> 20.144781
A2: Ried | B2: Jurak | C2: Midzic | D2: Kebe | E2: Balde | F2: Brkic | G2: Zirngast | H2: Tchicamboud | I2: Kane | J2: Augustus | K2: Perovic | L2: Haider
B3: =DATEDIF(VLOOKUP(B2,$P$18:$Q$100,2,FALSE),TODAY(),"Y") -> 21 | C3: =DATEDIF(VLOOKUP(C2,$P$18:$Q$100,2,FALSE),TODAY(),"Y") -> 21 | D3: =DATEDIF(VLOOKUP(D2,$P$18:$Q$100,2,FALSE),TODAY(),"Y") -> 20 | E3: =DATEDIF(VLOOKUP(E2,$P$18:$Q$100,2,FALSE),TODAY(),"Y") -> 20 | F3: =DATEDIF(VLOOKUP(F2,$P$18:$Q$100,2,FALSE),TODAY(),"Y") -> 20 | G3: =DATEDIF(VLOOKUP(G2,$P$18:$Q$100,2,FALSE),TODAY(),"Y") -> 24 | H3: =DATEDIF(VLOOKUP(H2,$P$18:$Q$100,2,FALSE),TODAY(),"Y") -> 20 | I3: =DATEDIF(VLOOKUP(I2,$P$18:$Q$100,2,FALSE),TODAY(),"Y") -> 20 | ... L3: =DATEDIF(VLOOKUP(L2,$P$18:$Q$100,2,FALSE),TODAY(),"Y") -> 20 | N3: =AVERAGE(B3:M3) -> 20.545455
A5: Velden | B5: Jurak | C5: Midzic | D5: Kebe | E5: Balde | F5: Sanogo | G5: Zirngast | H5: Tchicamboud | I5: Kane | J5: Augustus | K5: Perovic | L5: Frimpong
B6: =DATEDIF(VLOOKUP(B5,$P$18:$Q$100,2,FALSE),TODAY(),"Y") -> 21 | C6: =DATEDIF(VLOOKUP(C5,$P$18:$Q$100,2,FALSE),TODAY(),"Y") -> 21 | D6: =DATEDIF(VLOOKUP(D5,$P$18:$Q$100,2,FALSE),TODAY(),"Y") -> 20 | E6: =DATEDIF(VLOOKUP(E5,$P$18:$Q$100,2,FALSE),TODAY(),"Y") -> 20 | F6: =DATEDIF(VLOOKUP(F5,$P$18:$Q$100,2,FALSE),TODAY(),"Y") -> 22 | G6: =DATEDIF(VLOOKUP(G5,$P$18:$Q$100,2,FALSE),TODAY(),"Y") -> 24 | H6: =DATEDIF(VLOOKUP(H5,$P$18:$Q$100,2,FALSE),TODAY(),"Y") -> 20 | I6: =DATEDIF(VLOOKUP(I5,$P$18:$Q$100,2,FALSE),TODAY(),"Y") -> 20 | ... L6: =DATEDIF(VLOOKUP(L5,$P$18:$Q$100,2,FALSE),TODAY(),"Y") -> 21 | N6: =AVERAGE(B6:M6) -> 20.818182
A8: Oedt | B8: Jurak | C8: Midzic | D8: Kebe | E8: Balde | F8: Lebersorger | G8: Zirngast | H8: Tchicamboud | I8: Dianko | J8: Fall | K8: Perovic | L8: Haider
B9: =DATEDIF(VLOOKUP(B8,$P$18:$Q$100,2,FALSE),TODAY(),"Y") -> 21 | C9: =DATEDIF(VLOOKUP(C8,$P$18:$Q$100,2,FALSE),TODAY(),"Y") -> 21 | D9: =DATEDIF(VLOOKUP(D8,$P$18:$Q$100,2,FALSE),TODAY(),"Y") -> 20 | E9: =DATEDIF(VLOOKUP(E8,$P$18:$Q$100,2,FALSE),TODAY(),"Y") -> 20 | F9: =DATEDIF(VLOOKUP(F8,$P$18:$Q$100,2,FALSE),TODAY(),"Y") -> 20 | G9: =DATEDIF(VLOOKUP(G8,$P$18:$Q$100,2,FALSE),TODAY(),"Y") -> 24 | H9: =DATEDIF(VLOOKUP(H8,$P$18:$Q$100,2,FALSE),TODAY(),"Y") -> 20 | I9: =DATEDIF(VLOOKUP(I8,$P$18:$Q$100,2,FALSE),TODAY(),"Y") -> 20 | ... L9: =DATEDIF(VLOOKUP(L8,$P$18:$Q$100,2,FALSE),TODAY(),"Y") -> 20 | N9: =AVERAGE(B9:M9) -> 20.545455
A11: Gurten | B11: Jurak | C11: Midzic | D11: Kebe | E11: Bauer | F11: Augustus | G11: Asgersson | H11: Tchicamboud | I11: Sanogo | J11: Fall | K11: Perovic | L11: Haider
B12: =DATEDIF(VLOOKUP(B11,$P$18:$Q$100,2,FALSE),TODAY(),"Y") -> 21 | C12: =DATEDIF(VLOOKUP(C11,$P$18:$Q$100,2,FALSE),TODAY(),"Y") -> 21 | D12: =DATEDIF(VLOOKUP(D11,$P$18:$Q$100,2,FALSE),TODAY(),"Y") -> 20 | E12: =DATEDIF(VLOOKUP(E11,$P$18:$Q$100,2,FALSE),TODAY(),"Y") -> 19 | F12: =DATEDIF(VLOOKUP(F11,$P$18:$Q$100,2,FALSE),TODAY(),"Y") -> 21 | G12: =DATEDIF(VLOOKUP(G11,$P$18:$Q$100,2,FALSE),TODAY(),"Y") -> 17 | H12: =DATEDIF(VLOOKUP(H11,$P$18:$Q$100,2,FALSE),TODAY(),"Y") -> 20 | I12: =DATEDIF(VLOOKUP(I11,$P$18:$Q$100,2,FALSE),TODAY(),"Y") -> 22 | ... L12: =DATEDIF(VLOOKUP(L11,$P$18:$Q$100,2,FALSE),TODAY(),"Y") -> 20 | N12: =AVERAGE(B12:M12) -> 20.090909
A14: Wallern | B14: Jurak | C14: Midzic | D14: Kebe | E14: Balde | F14: Augustus | G14: Lebersorger | H14: Tchicamboud | I14: Sanogo | J14: Dianko | K14: Perovic | L14: Haider
B15: =DATEDIF(VLOOKUP(B14,$P$18:$Q$100,2,FALSE),TODAY(),"Y") -> 21 | C15: =DATEDIF(VLOOKUP(C14,$P$18:$Q$100,2,FALSE),TODAY(),"Y") -> 21 | D15: =DATEDIF(VLOOKUP(D14,$P$18:$Q$100,2,FALSE),TODAY(),"Y") -> 20 | E15: =DATEDIF(VLOOKUP(E14,$P$18:$Q$100,2,FALSE),TODAY(),"Y") -> 20 | F15: =DATEDIF(VLOOKUP(F14,$P$18:$Q$100,2,FALSE),TODAY(),"Y") -> 21 | G15: =DATEDIF(VLOOKUP(G14,$P$18:$Q$100,2,FALSE),TODAY(),"Y") -> 20 | H15: =DATEDIF(VLOOKUP(H14,$P$18:$Q$100,2,FALSE),TODAY(),"Y") -> 20 | I15: =DATEDIF(VLOOKUP(I14,$P$18:$Q$100,2,FALSE),TODAY(),"Y") -> 22 | ... L15: =DATEDIF(VLOOKUP(L14,$P$18:$Q$100,2,FALSE),TODAY(),"Y") -> 20 | N15: =AVERAGE(B15:M15) -> 20.363636
A17: Weiz | B17: Jurak | C17: Midzic | D17: Kebe | E17: Balde | F17: Zirngast | G17: Lebersorger | H17: Tchicamboud | I17: Kane | J17: Dianko | K17: Perovic | L17: Haider
B18: =DATEDIF(VLOOKUP(B17,$P$18:$Q$100,2,FALSE),TODAY(),"Y") -> 21 | C18: =DATEDIF(VLOOKUP(C17,$P$18:$Q$100,2,FALSE),TODAY(),"Y") -> 21 | D18: =DATEDIF(VLOOKUP(D17,$P$18:$Q$100,2,FALSE),TODAY(),"Y") -> 20 | E18: =DATEDIF(VLOOKUP(E17,$P$18:$Q$100,2,FALSE),TODAY(),"Y") -> 20 | F18: =DATEDIF(VLOOKUP(F17,$P$18:$Q$100,2,FALSE),TODAY(),"Y") -> 24 | G18: =DATEDIF(VLOOKUP(G17,$P$18:$Q$100,2,FALSE),TODAY(),"Y") -> 20 | H18: =DATEDIF(VLOOKUP(H17,$P$18:$Q$100,2,FALSE),TODAY(),"Y") -> 20 | I18: =DATEDIF(VLOOKUP(I17,$P$18:$Q$100,2,FALSE),TODAY(),"Y") -> 20 | ... L18: =DATEDIF(VLOOKUP(L17,$P$18:$Q$100,2,FALSE),TODAY(),"Y") -> 20 | N18: =AVERAGE(B18:M18) -> 20.454545
P19: Jurak | Q19: 38475 | T19: 36
A20: DSC | B20: Jurak | C20: Midzic | D20: Kebe | E20: Balde | F20: Zirngast | G20: Sanogo | H20: Tchicamboud | I20: Kane | J20: Dianko | K20: Perovic | L20: Ilk | P20: Midzic | Q20: 38417
B21: =DATEDIF(VLOOKUP(B20,$P$18:$Q$100,2,FALSE),TODAY(),"Y") -> 21 | C21: =DATEDIF(VLOOKUP(C20,$P$18:$Q$100,2,FALSE),TODAY(),"Y") -> 21 | D21: =DATEDIF(VLOOKUP(D20,$P$18:$Q$100,2,FALSE),TODAY(),"Y") -> 20 | E21: =DATEDIF(VLOOKUP(E20,$P$18:$Q$100,2,FALSE),TODAY(),"Y") -> 20 | F21: =DATEDIF(VLOOKUP(F20,$P$18:$Q$100,2,FALSE),TODAY(),"Y") -> 24 | G21: =DATEDIF(VLOOKUP(G20,$P$18:$Q$100,2,FALSE),TODAY(),"Y") -> 22 | H21: =DATEDIF(VLOOKUP(H20,$P$18:$Q$100,2,FALSE),TODAY(),"Y") -> 20 | I21: =DATEDIF(VLOOKUP(I20,$P$18:$Q$100,2,FALSE),TODAY(),"Y") -> 20 | ... L21: =DATEDIF(VLOOKUP(L20,$P$18:$Q$100,2,FALSE),TODAY(),"Y") -> 19 | N21: =AVERAGE(B21:M21) -> 20.545455 | P21: Kebe | Q21: 38682
P22: Balde | Q22: 38548
A23: Gleisdorf | B23: Jurak | C23: Midzic | D23: Kebe | E23: Balde | F23: Zirngast | G23: Lebersorger | H23: Tchicamboud | I23: Augustus | J23: Dianko | K23: Perovic | L23: Haider | P23: Brkic | Q23: 38727
B24: =DATEDIF(VLOOKUP(B23,$P$18:$Q$100,2,FALSE),TODAY(),"Y") -> 21 | C24: =DATEDIF(VLOOKUP(C23,$P$18:$Q$100,2,FALSE),TODAY(),"Y") -> 21 | D24: =DATEDIF(VLOOKUP(D23,$P$18:$Q$100,2,FALSE),TODAY(),"Y") -> 20 | E24: =DATEDIF(VLOOKUP(E23,$P$18:$Q$100,2,FALSE),TODAY(),"Y") -> 20 | F24: =DATEDIF(VLOOKUP(F23,$P$18:$Q$100,2,FALSE),TODAY(),"Y") -> 24 | G24: =DATEDIF(VLOOKUP(G23,$P$18:$Q$100,2,FALSE),TODAY(),"Y") -> 20 | H24: =DATEDIF(VLOOKUP(H23,$P$18:$Q$100,2,FALSE),TODAY(),"Y") -> 20 | I24: =DATEDIF(VLOOKUP(I23,$P$18:$Q$100,2,FALSE),TODAY(),"Y") -> 21 | ... L24: =DATEDIF(VLOOKUP(L23,$P$18:$Q$100,2,FALSE),TODAY(),"Y") -> 20 | N24: =AVERAGE(B24:M24) -> 20.545455 | P24: Zirngast | Q24: 37276
P25: Tchicamboud | Q25: 38694
A26: Lafnitz | B26: Jurak | C26: Midzic | D26: Kebe | E26: Balde | F26: Zirngast | G26: Lebersorger | H26: Tchicamboud | I26: Augustus | J26: Sanogo | K26: Perovic | L26: Haider | P26: Kane | Q26: 38819
B27: =DATEDIF(VLOOKUP(B26,$P$18:$Q$100,2,FALSE),TODAY(),"Y") -> 21 | C27: =DATEDIF(VLOOKUP(C26,$P$18:$Q$100,2,FALSE),TODAY(),"Y") -> 21 | D27: =DATEDIF(VLOOKUP(D26,$P$18:$Q$100,2,FALSE),TODAY(),"Y") -> 20 | E27: =DATEDIF(VLOOKUP(E26,$P$18:$Q$100,2,FALSE),TODAY(),"Y") -> 20 | F27: =DATEDIF(VLOOKUP(F26,$P$18:$Q$100,2,FALSE),TODAY(),"Y") -> 24 | G27: =DATEDIF(VLOOKUP(G26,$P$18:$Q$100,2,FALSE),TODAY(),"Y") -> 20 | H27: =DATEDIF(VLOOKUP(H26,$P$18:$Q$100,2,FALSE),TODAY(),"Y") -> 20 | I27: =DATEDIF(VLOOKUP(I26,$P$18:$Q$100,2,FALSE),TODAY(),"Y") -> 21 | ... L27: =DATEDIF(VLOOKUP(L26,$P$18:$Q$100,2,FALSE),TODAY(),"Y") -> 20 | N27: =AVERAGE(B27:M27) -> 20.727273 | P27: Augustus | Q27: 38475
P28: Perovic | Q28: 38916
A29: Kalsdorf | B29: Jurak | C29: Midzic | D29: Kebe | E29: Balde | F29: Zirngast | G29: Lebersorger | H29: Tchicamboud | I29: Augustus | J29: Sanogo | K29: Perovic | L29: Haider | P29: Haider | Q29: 38600
B30: =DATEDIF(VLOOKUP(B29,$P$18:$Q$100,2,FALSE),TODAY(),"Y") -> 21 | C30: =DATEDIF(VLOOKUP(C29,$P$18:$Q$100,2,FALSE),TODAY(),"Y") -> 21 | D30: =DATEDIF(VLOOKUP(D29,$P$18:$Q$100,2,FALSE),TODAY(),"Y") -> 20 | E30: =DATEDIF(VLOOKUP(E29,$P$18:$Q$100,2,FALSE),TODAY(),"Y") -> 20 | F30: =DATEDIF(VLOOKUP(F29,$P$18:$Q$100,2,FALSE),TODAY(),"Y") -> 24 | G30: =DATEDIF(VLOOKUP(G29,$P$18:$Q$100,2,FALSE),TODAY(),"Y") -> 20 | H30: =DATEDIF(VLOOKUP(H29,$P$18:$Q$100,2,FALSE),TODAY(),"Y") -> 20 | I30: =DATEDIF(VLOOKUP(I29,$P$18:$Q$100,2,FALSE),TODAY(),"Y") -> 21 | ... L30: =DATEDIF(VLOOKUP(L29,$P$18:$Q$100,2,FALSE),TODAY(),"Y") -> 20 | N30: =AVERAGE(B30:M30) -> 20.727273 | P30: Frimpong | Q30: 38335
P31: Sanogo | Q31: 37927
A32: Dietach | B32: Jurak | C32: Midzic | D32: Kebe | E32: Balde | F32: Zirngast | G32: Lebersorger | H32: Tchicamboud | I32: Augustus | J32: Dianko | K32: Perovic | L32: Haider | P32: Lebersorger | Q32: 38512
B33: =DATEDIF(VLOOKUP(B32,$P$18:$Q$100,2,FALSE),TODAY(),"Y") -> 21 | C33: =DATEDIF(VLOOKUP(C32,$P$18:$Q$100,2,FALSE),TODAY(),"Y") -> 21 | D33: =DATEDIF(VLOOKUP(D32,$P$18:$Q$100,2,FALSE),TODAY(),"Y") -> 20 | E33: =DATEDIF(VLOOKUP(E32,$P$18:$Q$100,2,FALSE),TODAY(),"Y") -> 20 | F33: =DATEDIF(VLOOKUP(F32,$P$18:$Q$100,2,FALSE),TODAY(),"Y") -> 24 | G33: =DATEDIF(VLOOKUP(G32,$P$18:$Q$100,2,FALSE),TODAY(),"Y") -> 20 | H33: =DATEDIF(VLOOKUP(H32,$P$18:$Q$100,2,FALSE),TODAY(),"Y") -> 20 | I33: =DATEDIF(VLOOKUP(I32,$P$18:$Q$100,2,FALSE),TODAY(),"Y") -> 21 | ... L33: =DATEDIF(VLOOKUP(L32,$P$18:$Q$100,2,FALSE),TODAY(),"Y") -> 20 | N33: =AVERAGE(B33:M33) -> 20.545455 | P33: Dianko | Q33: 38513
P34: Fall | Q34: 38448
A35: WAC | B35: Jurak | C35: Midzic | D35: Ilk | E35: Balde | F35: Zirngast | G35: Lebersorger | H35: Tchicamboud | I35: Augustus | J35: Diallo | K35: Perovic | L35: Kane | P35: Bauer | Q35: 39162
B36: =DATEDIF(VLOOKUP(B35,$P$18:$Q$100,2,FALSE),TODAY(),"Y") -> 21 | C36: =DATEDIF(VLOOKUP(C35,$P$18:$Q$100,2,FALSE),TODAY(),"Y") -> 21 | D36: =DATEDIF(VLOOKUP(D35,$P$18:$Q$100,2,FALSE),TODAY(),"Y") -> 19 | E36: =DATEDIF(VLOOKUP(E35,$P$18:$Q$100,2,FALSE),TODAY(),"Y") -> 20 | F36: =DATEDIF(VLOOKUP(F35,$P$18:$Q$100,2,FALSE),TODAY(),"Y") -> 24 | G36: =DATEDIF(VLOOKUP(G35,$P$18:$Q$100,2,FALSE),TODAY(),"Y") -> 20 | H36: =DATEDIF(VLOOKUP(H35,$P$18:$Q$100,2,FALSE),TODAY(),"Y") -> 20 | I36: =DATEDIF(VLOOKUP(I35,$P$18:$Q$100,2,FALSE),TODAY(),"Y") -> 21 | ... L36: =DATEDIF(VLOOKUP(L35,$P$18:$Q$100,2,FALSE),TODAY(),"Y") -> 20 | N36: =AVERAGE(B36:M36) -> 20.545455 | P36: Asgersson | Q36: 39597
P37: Ilk | Q37: 39178
A38: Voitsberg | B38: Schillinger | C38: Midzic | D38: Kebe | E38: Balde | F38: Zirngast | G38: Lebersorger | H38: Tchicamboud | I38: Mohammad | J38: Haider | K38: Perovic | L38: Kane | P38: Diallo | Q38: 38410
B39: =DATEDIF(VLOOKUP(B38,$P$18:$Q$100,2,FALSE),TODAY(),"Y") -> 18 | C39: =DATEDIF(VLOOKUP(C38,$P$18:$Q$100,2,FALSE),TODAY(),"Y") -> 21 | D39: =DATEDIF(VLOOKUP(D38,$P$18:$Q$100,2,FALSE),TODAY(),"Y") -> 20 | E39: =DATEDIF(VLOOKUP(E38,$P$18:$Q$100,2,FALSE),TODAY(),"Y") -> 20 | F39: =DATEDIF(VLOOKUP(F38,$P$18:$Q$100,2,FALSE),TODAY(),"Y") -> 24 | G39: =DATEDIF(VLOOKUP(G38,$P$18:$Q$100,2,FALSE),TODAY(),"Y") -> 20 | H39: =DATEDIF(VLOOKUP(H38,$P$18:$Q$100,2,FALSE),TODAY(),"Y") -> 20 | I39: =DATEDIF(VLOOKUP(I38,$P$18:$Q$100,2,FALSE),TODAY(),"Y") -> 21 | ... L39: =DATEDIF(VLOOKUP(L38,$P$18:$Q$100,2,FALSE),TODAY(),"Y") -> 20 | N39: =AVERAGE(B39:M39) -> 20.272727 | P39: Schillinger | Q39: 39226
P40: Mohammad | Q40: 38395
A41: St. Anna | B41: Jurak | C41: Kone | D41: Ilk | E41: Balde | F41: Zirngast | G41: Lebersorger | H41: Tchicamboud | I41: Mohammad | J41: Haider | K41: Perovic | L41: Kane | P41: Kone | Q41: 38718
B42: =DATEDIF(VLOOKUP(B41,$P$18:$Q$100,2,FALSE),TODAY(),"Y") -> 21 | C42: =DATEDIF(VLOOKUP(C41,$P$18:$Q$100,2,FALSE),TODAY(),"Y") -> 20 | D42: =DATEDIF(VLOOKUP(D41,$P$18:$Q$100,2,FALSE),TODAY(),"Y") -> 19 | E42: =DATEDIF(VLOOKUP(E41,$P$18:$Q$100,2,FALSE),TODAY(),"Y") -> 20 | F42: =DATEDIF(VLOOKUP(F41,$P$18:$Q$100,2,FALSE),TODAY(),"Y") -> 24 | G42: =DATEDIF(VLOOKUP(G41,$P$18:$Q$100,2,FALSE),TODAY(),"Y") -> 20 | H42: =DATEDIF(VLOOKUP(H41,$P$18:$Q$100,2,FALSE),TODAY(),"Y") -> 20 | I42: =DATEDIF(VLOOKUP(I41,$P$18:$Q$100,2,FALSE),TODAY(),"Y") -> 21 | ... L42: =DATEDIF(VLOOKUP(L41,$P$18:$Q$100,2,FALSE),TODAY(),"Y") -> 20 | N42: =AVERAGE(B42:M42) -> 20.363636 | P42: Pursall | Q42: 38062
P43: Traun | Q43: 39118
A44: Treibach | B44: Jurak | C44: Kone | D44: Ilk | E44: Pursall | F44: Zirngast | G44: Lebersorger | H44: Tchicamboud | I44: Augustus | J44: Midzic | K44: Perovic | L44: Kane | P44: Diakite | Q44: 39260
B45: =DATEDIF(VLOOKUP(B44,$P$18:$Q$100,2,FALSE),TODAY(),"Y") -> 21 | C45: =DATEDIF(VLOOKUP(C44,$P$18:$Q$100,2,FALSE),TODAY(),"Y") -> 20 | D45: =DATEDIF(VLOOKUP(D44,$P$18:$Q$100,2,FALSE),TODAY(),"Y") -> 19 | E45: =DATEDIF(VLOOKUP(E44,$P$18:$Q$100,2,FALSE),TODAY(),"Y") -> 22 | F45: =DATEDIF(VLOOKUP(F44,$P$18:$Q$100,2,FALSE),TODAY(),"Y") -> 24 | G45: =DATEDIF(VLOOKUP(G44,$P$18:$Q$100,2,FALSE),TODAY(),"Y") -> 20 | H45: =DATEDIF(VLOOKUP(H44,$P$18:$Q$100,2,FALSE),TODAY(),"Y") -> 20 | I45: =DATEDIF(VLOOKUP(I44,$P$18:$Q$100,2,FALSE),TODAY(),"Y") -> 21 | ... L45: =DATEDIF(VLOOKUP(L44,$P$18:$Q$100,2,FALSE),TODAY(),"Y") -> 20 | N45: =AVERAGE(B45:M45) -> 20.636364 | P45: Krapf | Q45: 39689
...

Sheet Altach Juniors
N1: =AVERAGE(N2:N99) -> 19.690909
A2: Lustenau | B2: Piffer | C2: Müller | D2: De Man | E2: Abdiji | F2: Gruber | G2: Vonbrül | H2: Muslioski | I2: Krstovic | J2: Madritsch | K2: Mahic | L2: Sismanlar
B3: =DATEDIF(VLOOKUP(B2,$P$18:$Q$100,2,FALSE),TODAY(),"Y") -> 20 | C3: =DATEDIF(VLOOKUP(C2,$P$18:$Q$100,2,FALSE),TODAY(),"Y") -> 17 | D3: =DATEDIF(VLOOKUP(D2,$P$18:$Q$100,2,FALSE),TODAY(),"Y") -> 19 | E3: =DATEDIF(VLOOKUP(E2,$P$18:$Q$100,2,FALSE),TODAY(),"Y") -> 19 | F3: =DATEDIF(VLOOKUP(F2,$P$18:$Q$100,2,FALSE),TODAY(),"Y") -> 19 | G3: =DATEDIF(VLOOKUP(G2,$P$18:$Q$100,2,FALSE),TODAY(),"Y") -> 18 | H3: =DATEDIF(VLOOKUP(H2,$P$18:$Q$100,2,FALSE),TODAY(),"Y") -> 23 | I3: =DATEDIF(VLOOKUP(I2,$P$18:$Q$100,2,FALSE),TODAY(),"Y") -> 17 | ... L3: =DATEDIF(VLOOKUP(L2,$P$18:$Q$100,2,FALSE),TODAY(),"Y") -> 22 | N3: =AVERAGE(B3:M3) -> 19.181818
A5: Lauterach | B5: Piffer | C5: Müller | D5: Milojevic | E5: Abdiji | F5: Gruber | G5: Vonbrül | H5: Fetahu | I5: Krstovic | J5: Madritsch | K5: Yalcin | L5: Sismanlar
B6: =DATEDIF(VLOOKUP(B5,$P$18:$Q$100,2,FALSE),TODAY(),"Y") -> 20 | C6: =DATEDIF(VLOOKUP(C5,$P$18:$Q$100,2,FALSE),TODAY(),"Y") -> 17 | D6: =DATEDIF(VLOOKUP(D5,$P$18:$Q$100,2,FALSE),TODAY(),"Y") -> 21 | E6: =DATEDIF(VLOOKUP(E5,$P$18:$Q$100,2,FALSE),TODAY(),"Y") -> 19 | F6: =DATEDIF(VLOOKUP(F5,$P$18:$Q$100,2,FALSE),TODAY(),"Y") -> 19 | G6: =DATEDIF(VLOOKUP(G5,$P$18:$Q$100,2,FALSE),TODAY(),"Y") -> 18 | H6: =DATEDIF(VLOOKUP(H5,$P$18:$Q$100,2,FALSE),TODAY(),"Y") -> 23 | I6: =DATEDIF(VLOOKUP(I5,$P$18:$Q$100,2,FALSE),TODAY(),"Y") -> 17 | ... L6: =DATEDIF(VLOOKUP(L5,$P$18:$Q$100,2,FALSE),TODAY(),"Y") -> 22 | N6: =AVERAGE(B6:M6) -> 19.727273
A8: Bischofshofen | B8: Piffer | C8: Müller | D8: De Man | E8: Abdiji | F8: Gruber | G8: Vonbrül | H8: Oberwaditzer | I8: Krstovic | J8: Yabantas | K8: Muslioski | L8: Hanak
B9: =DATEDIF(VLOOKUP(B8,$P$18:$Q$100,2,FALSE),TODAY(),"Y") -> 20 | C9: =DATEDIF(VLOOKUP(C8,$P$18:$Q$100,2,FALSE),TODAY(),"Y") -> 17 | D9: =DATEDIF(VLOOKUP(D8,$P$18:$Q$100,2,FALSE),TODAY(),"Y") -> 19 | E9: =DATEDIF(VLOOKUP(E8,$P$18:$Q$100,2,FALSE),TODAY(),"Y") -> 19 | F9: =DATEDIF(VLOOKUP(F8,$P$18:$Q$100,2,FALSE),TODAY(),"Y") -> 19 | G9: =DATEDIF(VLOOKUP(G8,$P$18:$Q$100,2,FALSE),TODAY(),"Y") -> 18 | H9: =DATEDIF(VLOOKUP(H8,$P$18:$Q$100,2,FALSE),TODAY(),"Y") -> 20 | I9: =DATEDIF(VLOOKUP(I8,$P$18:$Q$100,2,FALSE),TODAY(),"Y") -> 17 | ... L9: =DATEDIF(VLOOKUP(L8,$P$18:$Q$100,2,FALSE),TODAY(),"Y") -> 19 | N9: =AVERAGE(B9:M9) -> 19.363636
A11: Imst | B11: Piffer | C11: Müller | D11: Sismanlar | E11: Abdiji | F11: Gruber | G11: Vonbrül | H11: Oberwaditzer | I11: Krstovic | J11: Yabantas | K11: Muslioski | L11: Madritsch
B12: =DATEDIF(VLOOKUP(B11,$P$18:$Q$100,2,FALSE),TODAY(),"Y") -> 20 | C12: =DATEDIF(VLOOKUP(C11,$P$18:$Q$100,2,FALSE),TODAY(),"Y") -> 17 | D12: =DATEDIF(VLOOKUP(D11,$P$18:$Q$100,2,FALSE),TODAY(),"Y") -> 22 | E12: =DATEDIF(VLOOKUP(E11,$P$18:$Q$100,2,FALSE),TODAY(),"Y") -> 19 | F12: =DATEDIF(VLOOKUP(F11,$P$18:$Q$100,2,FALSE),TODAY(),"Y") -> 19 | G12: =DATEDIF(VLOOKUP(G11,$P$18:$Q$100,2,FALSE),TODAY(),"Y") -> 18 | H12: =DATEDIF(VLOOKUP(H11,$P$18:$Q$100,2,FALSE),TODAY(),"Y") -> 20 | I12: =DATEDIF(VLOOKUP(I11,$P$18:$Q$100,2,FALSE),TODAY(),"Y") -> 17 | ... L12: =DATEDIF(VLOOKUP(L11,$P$18:$Q$100,2,FALSE),TODAY(),"Y") -> 20 | N12: =AVERAGE(B12:M12) -> 19.727273
A14: Schwaz | B14: Ender | C14: Müller | D14: Sismanlar | E14: Abdiji | F14: Gruber | G14: De Man | H14: Oberwaditzer | I14: Kuster | J14: Yabantas | K14: Muslioski | L14: Hanak
B15: =DATEDIF(VLOOKUP(B14,$P$18:$Q$100,2,FALSE),TODAY(),"Y") -> 20 | C15: =DATEDIF(VLOOKUP(C14,$P$18:$Q$100,2,FALSE),TODAY(),"Y") -> 17 | D15: =DATEDIF(VLOOKUP(D14,$P$18:$Q$100,2,FALSE),TODAY(),"Y") -> 22 | E15: =DATEDIF(VLOOKUP(E14,$P$18:$Q$100,2,FALSE),TODAY(),"Y") -> 19 | F15: =DATEDIF(VLOOKUP(F14,$P$18:$Q$100,2,FALSE),TODAY(),"Y") -> 19 | G15: =DATEDIF(VLOOKUP(G14,$P$18:$Q$100,2,FALSE),TODAY(),"Y") -> 19 | H15: =DATEDIF(VLOOKUP(H14,$P$18:$Q$100,2,FALSE),TODAY(),"Y") -> 20 | I15: =DATEDIF(VLOOKUP(I14,$P$18:$Q$100,2,FALSE),TODAY(),"Y") -> 18 | ... L15: =DATEDIF(VLOOKUP(L14,$P$18:$Q$100,2,FALSE),TODAY(),"Y") -> 19 | N15: =AVERAGE(B15:M15) -> 19.818182
A17: Kuchl | B17: Ender | C17: Yilmaz | D17: Sismanlar | E17: Abdiji | F17: Gruber | G17: De Man | H17: Basar | I17: Krstovic | J17: Yabantas | K17: Muslioski | L17: Vonbrül
B18: =DATEDIF(VLOOKUP(B17,$P$18:$Q$100,2,FALSE),TODAY(),"Y") -> 20 | C18: =DATEDIF(VLOOKUP(C17,$P$18:$Q$100,2,FALSE),TODAY(),"Y") -> 18 | D18: =DATEDIF(VLOOKUP(D17,$P$18:$Q$100,2,FALSE),TODAY(),"Y") -> 22 | E18: =DATEDIF(VLOOKUP(E17,$P$18:$Q$100,2,FALSE),TODAY(),"Y") -> 19 | F18: =DATEDIF(VLOOKUP(F17,$P$18:$Q$100,2,FALSE),TODAY(),"Y") -> 19 | G18: =DATEDIF(VLOOKUP(G17,$P$18:$Q$100,2,FALSE),TODAY(),"Y") -> 19 | H18: =DATEDIF(VLOOKUP(H17,$P$18:$Q$100,2,FALSE),TODAY(),"Y") -> 18 | I18: =DATEDIF(VLOOKUP(I17,$P$18:$Q$100,2,FALSE),TODAY(),"Y") -> 17 | ... L18: =DATEDIF(VLOOKUP(L17,$P$18:$Q$100,2,FALSE),TODAY(),"Y") -> 18 | N18: =AVERAGE(B18:M18) -> 19.545455 | P18: Piffer | Q18: 38815 | T18: 33
P19: De Man | Q19: 39135
A20: Hohenems | B20: Ender | C20: Müller | D20: Milojevic | E20: Abdiji | F20: Gruber | G20: Madritsch | H20: Kronberger | I20: Krstovic | J20: Yabantas | K20: Muslioski | L20: Fetahu | P20: Müller | Q20: 39895
B21: =DATEDIF(VLOOKUP(B20,$P$18:$Q$100,2,FALSE),TODAY(),"Y") -> 20 | C21: =DATEDIF(VLOOKUP(C20,$P$18:$Q$100,2,FALSE),TODAY(),"Y") -> 17 | D21: =DATEDIF(VLOOKUP(D20,$P$18:$Q$100,2,FALSE),TODAY(),"Y") -> 21 | E21: =DATEDIF(VLOOKUP(E20,$P$18:$Q$100,2,FALSE),TODAY(),"Y") -> 19 | F21: =DATEDIF(VLOOKUP(F20,$P$18:$Q$100,2,FALSE),TODAY(),"Y") -> 19 | G21: =DATEDIF(VLOOKUP(G20,$P$18:$Q$100,2,FALSE),TODAY(),"Y") -> 20 | H21: =DATEDIF(VLOOKUP(H20,$P$18:$Q$100,2,FALSE),TODAY(),"Y") -> 24 | I21: =DATEDIF(VLOOKUP(I20,$P$18:$Q$100,2,FALSE),TODAY(),"Y") -> 17 | ... L21: =DATEDIF(VLOOKUP(L20,$P$18:$Q$100,2,FALSE),TODAY(),"Y") -> 23 | N21: =AVERAGE(B21:M21) -> 20.454545 | P21: Abdiji | Q21: 38965
P22: Gruber | Q22: 39123
A23: Kufstein | B23: Ender | C23: Müller | D23: Yilmaz | E23: Abdiji | F23: Gruber | G23: Madritsch | H23: Kronberger | I23: Krstovic | J23: De Man | K23: Muslioski | L23: Hanak | P23: Krstovic | Q23: 39689
B24: =DATEDIF(VLOOKUP(B23,$P$18:$Q$100,2,FALSE),TODAY(),"Y") -> 20 | C24: =DATEDIF(VLOOKUP(C23,$P$18:$Q$100,2,FALSE),TODAY(),"Y") -> 17 | D24: =DATEDIF(VLOOKUP(D23,$P$18:$Q$100,2,FALSE),TODAY(),"Y") -> 18 | E24: =DATEDIF(VLOOKUP(E23,$P$18:$Q$100,2,FALSE),TODAY(),"Y") -> 19 | F24: =DATEDIF(VLOOKUP(F23,$P$18:$Q$100,2,FALSE),TODAY(),"Y") -> 19 | G24: =DATEDIF(VLOOKUP(G23,$P$18:$Q$100,2,FALSE),TODAY(),"Y") -> 20 | H24: =DATEDIF(VLOOKUP(H23,$P$18:$Q$100,2,FALSE),TODAY(),"Y") -> 24 | I24: =DATEDIF(VLOOKUP(I23,$P$18:$Q$100,2,FALSE),TODAY(),"Y") -> 17 | ... L24: =DATEDIF(VLOOKUP(L23,$P$18:$Q$100,2,FALSE),TODAY(),"Y") -> 19 | N24: =AVERAGE(B24:M24) -> 19.545455 | P24: Vonbrül | Q24: 39460
P25: Muslioski | Q25: 37739
A26: St. Johann | B26: Ender | C26: Müller | D26: Yabantas | E26: Abdiji | F26: Gruber | G26: Kuster | H26: Sismanlar | I26: Krstovic | J26: De Man | K26: Muslioski | L26: Hanak | P26: Mahic | Q26: 39654
B27: =DATEDIF(VLOOKUP(B26,$P$18:$Q$100,2,FALSE),TODAY(),"Y") -> 20 | C27: =DATEDIF(VLOOKUP(C26,$P$18:$Q$100,2,FALSE),TODAY(),"Y") -> 17 | D27: =DATEDIF(VLOOKUP(D26,$P$18:$Q$100,2,FALSE),TODAY(),"Y") -> 22 | E27: =DATEDIF(VLOOKUP(E26,$P$18:$Q$100,2,FALSE),TODAY(),"Y") -> 19 | F27: =DATEDIF(VLOOKUP(F26,$P$18:$Q$100,2,FALSE),TODAY(),"Y") -> 19 | G27: =DATEDIF(VLOOKUP(G26,$P$18:$Q$100,2,FALSE),TODAY(),"Y") -> 18 | H27: =DATEDIF(VLOOKUP(H26,$P$18:$Q$100,2,FALSE),TODAY(),"Y") -> 22 | I27: =DATEDIF(VLOOKUP(I26,$P$18:$Q$100,2,FALSE),TODAY(),"Y") -> 17 | ... L27: =DATEDIF(VLOOKUP(L26,$P$18:$Q$100,2,FALSE),TODAY(),"Y") -> 19 | N27: =AVERAGE(B27:M27) -> 19.545455 | P27: Sismanlar | Q27: 38020
P28: Madritsch | Q28: 38566
A29: Seekirchen | B29: Petrovic | C29: Thalmann | D29: Yilmaz | E29: De Man | F29: Gruber | G29: Abdiji | H29: Hodzic | I29: Yabantas | J29: Krstovic | K29: Maretic | L29: Mahic | P29: Yalcin | Q29: 38152
B30: =DATEDIF(VLOOKUP(B29,$P$18:$Q$100,2,FALSE),TODAY(),"Y") -> 19 | C30: =DATEDIF(VLOOKUP(C29,$P$18:$Q$100,2,FALSE),TODAY(),"Y") -> 20 | D30: =DATEDIF(VLOOKUP(D29,$P$18:$Q$100,2,FALSE),TODAY(),"Y") -> 18 | E30: =DATEDIF(VLOOKUP(E29,$P$18:$Q$100,2,FALSE),TODAY(),"Y") -> 19 | F30: =DATEDIF(VLOOKUP(F29,$P$18:$Q$100,2,FALSE),TODAY(),"Y") -> 19 | G30: =DATEDIF(VLOOKUP(G29,$P$18:$Q$100,2,FALSE),TODAY(),"Y") -> 19 | H30: =DATEDIF(VLOOKUP(H29,$P$18:$Q$100,2,FALSE),TODAY(),"Y") -> 17 | I30: =DATEDIF(VLOOKUP(I29,$P$18:$Q$100,2,FALSE),TODAY(),"Y") -> 22 | ... L30: =DATEDIF(VLOOKUP(L29,$P$18:$Q$100,2,FALSE),TODAY(),"Y") -> 17 | N30: =AVERAGE(B30:M30) -> 18.636364 | P30: Milojevic | Q30: 38392
P31: Fetahu | Q31: 37447
A32: Reichenau | B32: Ender | C32: Thalmann | D32: Basar | E32: De Man | F32: Gruber | G32: Abdiji | H32: Kronberger | I32: Yabantas | J32: Krstovic | K32: Sismanlar | L32: Fetahu | P32: Oberwaditzer | Q32: 38790
B33: =DATEDIF(VLOOKUP(B32,$P$18:$Q$100,2,FALSE),TODAY(),"Y") -> 20 | C33: =DATEDIF(VLOOKUP(C32,$P$18:$Q$100,2,FALSE),TODAY(),"Y") -> 20 | D33: =DATEDIF(VLOOKUP(D32,$P$18:$Q$100,2,FALSE),TODAY(),"Y") -> 18 | E33: =DATEDIF(VLOOKUP(E32,$P$18:$Q$100,2,FALSE),TODAY(),"Y") -> 19 | F33: =DATEDIF(VLOOKUP(F32,$P$18:$Q$100,2,FALSE),TODAY(),"Y") -> 19 | G33: =DATEDIF(VLOOKUP(G32,$P$18:$Q$100,2,FALSE),TODAY(),"Y") -> 19 | H33: =DATEDIF(VLOOKUP(H32,$P$18:$Q$100,2,FALSE),TODAY(),"Y") -> 24 | I33: =DATEDIF(VLOOKUP(I32,$P$18:$Q$100,2,FALSE),TODAY(),"Y") -> 22 | ... L33: =DATEDIF(VLOOKUP(L32,$P$18:$Q$100,2,FALSE),TODAY(),"Y") -> 23 | N33: =AVERAGE(B33:M33) -> 20.272727 | P33: Yabantas | Q33: 38012
P34: Hanak | Q34: 39085
A35: Dornbirn | B35: Ender | C35: Thalmann | D35: Vonbrül | E35: Madritsch | F35: Gruber | G35: Abdiji | H35: Kronberger | I35: Müller | J35: Krstovic | K35: Sismanlar | L35: Fetahu | P35: Ender | Q35: 38728
B36: =DATEDIF(VLOOKUP(B35,$P$18:$Q$100,2,FALSE),TODAY(),"Y") -> 20 | C36: =DATEDIF(VLOOKUP(C35,$P$18:$Q$100,2,FALSE),TODAY(),"Y") -> 20 | D36: =DATEDIF(VLOOKUP(D35,$P$18:$Q$100,2,FALSE),TODAY(),"Y") -> 18 | E36: =DATEDIF(VLOOKUP(E35,$P$18:$Q$100,2,FALSE),TODAY(),"Y") -> 20 | F36: =DATEDIF(VLOOKUP(F35,$P$18:$Q$100,2,FALSE),TODAY(),"Y") -> 19 | G36: =DATEDIF(VLOOKUP(G35,$P$18:$Q$100,2,FALSE),TODAY(),"Y") -> 19 | H36: =DATEDIF(VLOOKUP(H35,$P$18:$Q$100,2,FALSE),TODAY(),"Y") -> 24 | I36: =DATEDIF(VLOOKUP(I35,$P$18:$Q$100,2,FALSE),TODAY(),"Y") -> 17 | ... L36: =DATEDIF(VLOOKUP(L35,$P$18:$Q$100,2,FALSE),TODAY(),"Y") -> 23 | N36: =AVERAGE(B36:M36) -> 19.909091 | P36: Kuster | Q36: 39538
P37: Yilmaz | Q37: 39427
A38: Saalfelden | B38: Ender | C38: De Man | D38: Vonbrül | E38: Madritsch | F38: Gruber | G38: Abdiji | H38: Kronberger | I38: Müller | J38: Kuster | K38: Sismanlar | L38: Hanak | P38: Basar | Q38: 39500
B39: =DATEDIF(VLOOKUP(B38,$P$18:$Q$100,2,FALSE),TODAY(),"Y") -> 20 | C39: =DATEDIF(VLOOKUP(C38,$P$18:$Q$100,2,FALSE),TODAY(),"Y") -> 19 | D39: =DATEDIF(VLOOKUP(D38,$P$18:$Q$100,2,FALSE),TODAY(),"Y") -> 18 | E39: =DATEDIF(VLOOKUP(E38,$P$18:$Q$100,2,FALSE),TODAY(),"Y") -> 20 | F39: =DATEDIF(VLOOKUP(F38,$P$18:$Q$100,2,FALSE),TODAY(),"Y") -> 19 | G39: =DATEDIF(VLOOKUP(G38,$P$18:$Q$100,2,FALSE),TODAY(),"Y") -> 19 | H39: =DATEDIF(VLOOKUP(H38,$P$18:$Q$100,2,FALSE),TODAY(),"Y") -> 24 | I39: =DATEDIF(VLOOKUP(I38,$P$18:$Q$100,2,FALSE),TODAY(),"Y") -> 17 | ... L39: =DATEDIF(VLOOKUP(L38,$P$18:$Q$100,2,FALSE),TODAY(),"Y") -> 19 | N39: =AVERAGE(B39:M39) -> 19.545455 | P39: Kronberger | Q39: 37302
P40: Petrovic | Q40: 38913
A41: Wals-Grünau | B41: Ender | C41: Yilmaz | D41: Vonbrül | E41: Zorlu | F41: Gruber | G41: Abdiji | H41: Krstovic | I41: Müller | J41: Kuster | K41: Sismanlar | L41: Hanak | P41: Thalmann | Q41: 38795
B42: =DATEDIF(VLOOKUP(B41,$P$18:$Q$100,2,FALSE),TODAY(),"Y") -> 20 | C42: =DATEDIF(VLOOKUP(C41,$P$18:$Q$100,2,FALSE),TODAY(),"Y") -> 18 | D42: =DATEDIF(VLOOKUP(D41,$P$18:$Q$100,2,FALSE),TODAY(),"Y") -> 18 | E42: =DATEDIF(VLOOKUP(E41,$P$18:$Q$100,2,FALSE),TODAY(),"Y") -> 22 | F42: =DATEDIF(VLOOKUP(F41,$P$18:$Q$100,2,FALSE),TODAY(),"Y") -> 19 | G42: =DATEDIF(VLOOKUP(G41,$P$18:$Q$100,2,FALSE),TODAY(),"Y") -> 19 | H42: =DATEDIF(VLOOKUP(H41,$P$18:$Q$100,2,FALSE),TODAY(),"Y") -> 17 | I42: =DATEDIF(VLOOKUP(I41,$P$18:$Q$100,2,FALSE),TODAY(),"Y") -> 17 | ... L42: =DATEDIF(VLOOKUP(L41,$P$18:$Q$100,2,FALSE),TODAY(),"Y") -> 19 | N42: =AVERAGE(B42:M42) -> 19 | P42: Hodzic | Q42: 39771
P43: Maretic | Q43: 39339
A44: Kitzbühel | B44: Ender | C44: De Man | D44: Muslioski | E44: Zorlu | F44: Gruber | G44: Abdiji | H44: Kronberger | I44: Müller | J44: Madritsch | K44: Sismanlar | L44: Hanak | P44: Zorlu | Q44: 37852
B45: =DATEDIF(VLOOKUP(B44,$P$18:$Q$100,2,FALSE),TODAY(),"Y") -> 20 | C45: =DATEDIF(VLOOKUP(C44,$P$18:$Q$100,2,FALSE),TODAY(),"Y") -> 19 | D45: =DATEDIF(VLOOKUP(D44,$P$18:$Q$100,2,FALSE),TODAY(),"Y") -> 23 | E45: =DATEDIF(VLOOKUP(E44,$P$18:$Q$100,2,FALSE),TODAY(),"Y") -> 22 | F45: =DATEDIF(VLOOKUP(F44,$P$18:$Q$100,2,FALSE),TODAY(),"Y") -> 19 | G45: =DATEDIF(VLOOKUP(G44,$P$18:$Q$100,2,FALSE),TODAY(),"Y") -> 19 | H45: =DATEDIF(VLOOKUP(H44,$P$18:$Q$100,2,FALSE),TODAY(),"Y") -> 24 | I45: =DATEDIF(VLOOKUP(I44,$P$18:$Q$100,2,FALSE),TODAY(),"Y") -> 17 | ... L45: =DATEDIF(VLOOKUP(L44,$P$18:$Q$100,2,FALSE),TODAY(),"Y") -> 19 | N45: =AVERAGE(B45:M45) -> 20.363636 | P45: de Freitas | Q45: 38724
...

Sheet Young Violets
N1: =AVERAGE(N2:N99) -> 21.169279
A2: St. Pölten | B2: Jusic | C2: Wojnar | D2: Ndukwe | E2: Radonjic | F2: Nisandzic | G2: Maybach | H2: Nnodim | I2: Österreicher | J2: Mörth | K2: Aleksa | L2: Hosiner
B3: =DATEDIF(VLOOKUP(B2,$P$18:$Q$100,2,FALSE),TODAY(),"Y") -> 21 | C3: =DATEDIF(VLOOKUP(C2,$P$18:$Q$100,2,FALSE),TODAY(),"Y") -> 20 | D3: =DATEDIF(VLOOKUP(D2,$P$18:$Q$100,2,FALSE),TODAY(),"Y") -> 18 | E3: =DATEDIF(VLOOKUP(E2,$P$18:$Q$100,2,FALSE),TODAY(),"Y") -> 20 | F3: =DATEDIF(VLOOKUP(F2,$P$18:$Q$100,2,FALSE),TODAY(),"Y") -> 19 | G3: =DATEDIF(VLOOKUP(G2,$P$18:$Q$100,2,FALSE),TODAY(),"Y") -> 18 | H3: =DATEDIF(VLOOKUP(H2,$P$18:$Q$100,2,FALSE),TODAY(),"Y") -> 18 | I3: =DATEDIF(VLOOKUP(I2,$P$18:$Q$100,2,FALSE),TODAY(),"Y") -> 20 | ... L3: =DATEDIF(VLOOKUP(L2,$P$18:$Q$100,2,FALSE),TODAY(),"Y") -> 37 | N3: =AVERAGE(B3:M3) -> 20.818182
A5: Klagenfurt | B5: Jusic | C5: Wojnar | D5: Fischer | E5: Radonjic | F5: Nisandzic | G5: Maybach | H5: Nnodim | I5: Österreicher | J5: Mörth | K5: Aleksa | L5: Hosiner
B6: =DATEDIF(VLOOKUP(B5,$P$18:$Q$100,2,FALSE),TODAY(),"Y") -> 21 | C6: =DATEDIF(VLOOKUP(C5,$P$18:$Q$100,2,FALSE),TODAY(),"Y") -> 20 | D6: =DATEDIF(VLOOKUP(D5,$P$18:$Q$100,2,FALSE),TODAY(),"Y") -> 19 | E6: =DATEDIF(VLOOKUP(E5,$P$18:$Q$100,2,FALSE),TODAY(),"Y") -> 20 | F6: =DATEDIF(VLOOKUP(F5,$P$18:$Q$100,2,FALSE),TODAY(),"Y") -> 19 | G6: =DATEDIF(VLOOKUP(G5,$P$18:$Q$100,2,FALSE),TODAY(),"Y") -> 18 | H6: =DATEDIF(VLOOKUP(H5,$P$18:$Q$100,2,FALSE),TODAY(),"Y") -> 18 | I6: =DATEDIF(VLOOKUP(I5,$P$18:$Q$100,2,FALSE),TODAY(),"Y") -> 20 | ... L6: =DATEDIF(VLOOKUP(L5,$P$18:$Q$100,2,FALSE),TODAY(),"Y") -> 37 | N6: =AVERAGE(B6:M6) -> 20.909091
A8: Admira | B8: Jusic | C8: Wojnar | D8: Fischer | E8: Lukic | F8: Nisandzic | G8: Ndukwe | H8: Nnodim | I8: Österreicher | J8: Mörth | K8: Schablas | L8: Hosiner
B9: =DATEDIF(VLOOKUP(B8,$P$18:$Q$100,2,FALSE),TODAY(),"Y") -> 21 | C9: =DATEDIF(VLOOKUP(C8,$P$18:$Q$100,2,FALSE),TODAY(),"Y") -> 20 | D9: =DATEDIF(VLOOKUP(D8,$P$18:$Q$100,2,FALSE),TODAY(),"Y") -> 19 | E9: =DATEDIF(VLOOKUP(E8,$P$18:$Q$100,2,FALSE),TODAY(),"Y") -> 20 | F9: =DATEDIF(VLOOKUP(F8,$P$18:$Q$100,2,FALSE),TODAY(),"Y") -> 19 | G9: =DATEDIF(VLOOKUP(G8,$P$18:$Q$100,2,FALSE),TODAY(),"Y") -> 18 | H9: =DATEDIF(VLOOKUP(H8,$P$18:$Q$100,2,FALSE),TODAY(),"Y") -> 18 | I9: =DATEDIF(VLOOKUP(I8,$P$18:$Q$100,2,FALSE),TODAY(),"Y") -> 20 | ... L9: =DATEDIF(VLOOKUP(L8,$P$18:$Q$100,2,FALSE),TODAY(),"Y") -> 37 | N9: =AVERAGE(B9:M9) -> 21.090909
A11: Rapid | B11: Jusic | C11: Wojnar | D11: Fischer | E11: Lukic | F11: Nisandzic | G11: Ndukwe | H11: Aleksa | I11: Österreicher | J11: Mörth | K11: Schablas | L11: Hosiner
B12: =DATEDIF(VLOOKUP(B11,$P$18:$Q$100,2,FALSE),TODAY(),"Y") -> 21 | C12: =DATEDIF(VLOOKUP(C11,$P$18:$Q$100,2,FALSE),TODAY(),"Y") -> 20 | D12: =DATEDIF(VLOOKUP(D11,$P$18:$Q$100,2,FALSE),TODAY(),"Y") -> 19 | E12: =DATEDIF(VLOOKUP(E11,$P$18:$Q$100,2,FALSE),TODAY(),"Y") -> 20 | F12: =DATEDIF(VLOOKUP(F11,$P$18:$Q$100,2,FALSE),TODAY(),"Y") -> 19 | G12: =DATEDIF(VLOOKUP(G11,$P$18:$Q$100,2,FALSE),TODAY(),"Y") -> 18 | H12: =DATEDIF(VLOOKUP(H11,$P$18:$Q$100,2,FALSE),TODAY(),"Y") -> 19 | I12: =DATEDIF(VLOOKUP(I11,$P$18:$Q$100,2,FALSE),TODAY(),"Y") -> 20 | ... L12: =DATEDIF(VLOOKUP(L11,$P$18:$Q$100,2,FALSE),TODAY(),"Y") -> 37 | N12: =AVERAGE(B12:M12) -> 21.181818
A14: Wels | B14: Jusic | C14: Wojnar | D14: Fischer | E14: Lukic | F14: Nisandzic | G14: Ilic | H14: Aleksa | I14: Österreicher | J14: Mörth | K14: Sawicki | L14: Hosiner
B15: =DATEDIF(VLOOKUP(B14,$P$18:$Q$100,2,FALSE),TODAY(),"Y") -> 21 | C15: =DATEDIF(VLOOKUP(C14,$P$18:$Q$100,2,FALSE),TODAY(),"Y") -> 20 | D15: =DATEDIF(VLOOKUP(D14,$P$18:$Q$100,2,FALSE),TODAY(),"Y") -> 19 | E15: =DATEDIF(VLOOKUP(E14,$P$18:$Q$100,2,FALSE),TODAY(),"Y") -> 20 | F15: =DATEDIF(VLOOKUP(F14,$P$18:$Q$100,2,FALSE),TODAY(),"Y") -> 19 | G15: =DATEDIF(VLOOKUP(G14,$P$18:$Q$100,2,FALSE),TODAY(),"Y") -> 21 | H15: =DATEDIF(VLOOKUP(H14,$P$18:$Q$100,2,FALSE),TODAY(),"Y") -> 19 | I15: =DATEDIF(VLOOKUP(I14,$P$18:$Q$100,2,FALSE),TODAY(),"Y") -> 20 | ... L15: =DATEDIF(VLOOKUP(L14,$P$18:$Q$100,2,FALSE),TODAY(),"Y") -> 37 | N15: =AVERAGE(B15:M15) -> 21.363636
A17: Vienna | B17: Jusic | C17: Wojnar | D17: Fischer | E17: Lukic | F17: Nisandzic | G17: Ilic | H17: Nnodim | I17: Österreicher | J17: Mörth | K17: Sawicki | L17: Hosiner
B18: =DATEDIF(VLOOKUP(B17,$P$18:$Q$100,2,FALSE),TODAY(),"Y") -> 21 | C18: =DATEDIF(VLOOKUP(C17,$P$18:$Q$100,2,FALSE),TODAY(),"Y") -> 20 | D18: =DATEDIF(VLOOKUP(D17,$P$18:$Q$100,2,FALSE),TODAY(),"Y") -> 19 | E18: =DATEDIF(VLOOKUP(E17,$P$18:$Q$100,2,FALSE),TODAY(),"Y") -> 20 | F18: =DATEDIF(VLOOKUP(F17,$P$18:$Q$100,2,FALSE),TODAY(),"Y") -> 19 | G18: =DATEDIF(VLOOKUP(G17,$P$18:$Q$100,2,FALSE),TODAY(),"Y") -> 21 | H18: =DATEDIF(VLOOKUP(H17,$P$18:$Q$100,2,FALSE),TODAY(),"Y") -> 18 | I18: =DATEDIF(VLOOKUP(I17,$P$18:$Q$100,2,FALSE),TODAY(),"Y") -> 20 | ... L18: =DATEDIF(VLOOKUP(L17,$P$18:$Q$100,2,FALSE),TODAY(),"Y") -> 37 | N18: =AVERAGE(B18:M18) -> 21.272727 | P18: Jusic | Q18: 38482 | T18: 33
P19: Wojnar | Q19: 38627
A20: Sturm | B20: Jusic | C20: Schablas | D20: Fischer | E20: Lukic | F20: Nisandzic | G20: Zdichynec | H20: Nnodim | I20: Ndukwe | J20: Mörth | K20: Aleksa | L20: Hosiner | P20: Radonjic | Q20: 38620
B21: =DATEDIF(VLOOKUP(B20,$P$18:$Q$100,2,FALSE),TODAY(),"Y") -> 21 | C21: =DATEDIF(VLOOKUP(C20,$P$18:$Q$100,2,FALSE),TODAY(),"Y") -> 21 | D21: =DATEDIF(VLOOKUP(D20,$P$18:$Q$100,2,FALSE),TODAY(),"Y") -> 19 | E21: =DATEDIF(VLOOKUP(E20,$P$18:$Q$100,2,FALSE),TODAY(),"Y") -> 20 | F21: =DATEDIF(VLOOKUP(F20,$P$18:$Q$100,2,FALSE),TODAY(),"Y") -> 19 | G21: =DATEDIF(VLOOKUP(G20,$P$18:$Q$100,2,FALSE),TODAY(),"Y") -> 24 | H21: =DATEDIF(VLOOKUP(H20,$P$18:$Q$100,2,FALSE),TODAY(),"Y") -> 18 | I21: =DATEDIF(VLOOKUP(I20,$P$18:$Q$100,2,FALSE),TODAY(),"Y") -> 18 | ... L21: =DATEDIF(VLOOKUP(L20,$P$18:$Q$100,2,FALSE),TODAY(),"Y") -> 37 | N21: =AVERAGE(B21:M21) -> 21.363636 | P21: Ndukwe | Q21: 39510
P22: Wojnar | Q22: 38627
A23: Amstetten | B23: Jusic | C23: Schablas | D23: Fischer | E23: Lukic | F23: Nisandzic | G23: Wojnar | H23: Nnodim | I23: Ndukwe | J23: Mörth | K23: Deshishku | L23: Hosiner | P23: Nnodim | Q23: 39422
B24: =DATEDIF(VLOOKUP(B23,$P$18:$Q$100,2,FALSE),TODAY(),"Y") -> 21 | C24: =DATEDIF(VLOOKUP(C23,$P$18:$Q$100,2,FALSE),TODAY(),"Y") -> 21 | D24: =DATEDIF(VLOOKUP(D23,$P$18:$Q$100,2,FALSE),TODAY(),"Y") -> 19 | E24: =DATEDIF(VLOOKUP(E23,$P$18:$Q$100,2,FALSE),TODAY(),"Y") -> 20 | F24: =DATEDIF(VLOOKUP(F23,$P$18:$Q$100,2,FALSE),TODAY(),"Y") -> 19 | G24: =DATEDIF(VLOOKUP(G23,$P$18:$Q$100,2,FALSE),TODAY(),"Y") -> 20 | H24: =DATEDIF(VLOOKUP(H23,$P$18:$Q$100,2,FALSE),TODAY(),"Y") -> 18 | I24: =DATEDIF(VLOOKUP(I23,$P$18:$Q$100,2,FALSE),TODAY(),"Y") -> 18 | ... L24: =DATEDIF(VLOOKUP(L23,$P$18:$Q$100,2,FALSE),TODAY(),"Y") -> 37 | N24: =AVERAGE(B24:M24) -> 20.909091 | P24: Maybach | Q24: 39430
P25: Nisandzic | Q25: 38906
A26: Lustenau | B26: Jusic | C26: Abdi | D26: Fischer | E26: Lukic | F26: Sawicki | G26: Wojnar | H26: Nnodim | I26: Ndukwe | J26: Mörth | K26: Zdichynec | L26: Österreicher | P26: Mörth | Q26: 39143
B27: =DATEDIF(VLOOKUP(B26,$P$18:$Q$100,2,FALSE),TODAY(),"Y") -> 21 | C27: =DATEDIF(VLOOKUP(C26,$P$18:$Q$100,2,FALSE),TODAY(),"Y") -> 20 | D27: =DATEDIF(VLOOKUP(D26,$P$18:$Q$100,2,FALSE),TODAY(),"Y") -> 19 | E27: =DATEDIF(VLOOKUP(E26,$P$18:$Q$100,2,FALSE),TODAY(),"Y") -> 20 | F27: =DATEDIF(VLOOKUP(F26,$P$18:$Q$100,2,FALSE),TODAY(),"Y") -> 20 | G27: =DATEDIF(VLOOKUP(G26,$P$18:$Q$100,2,FALSE),TODAY(),"Y") -> 20 | H27: =DATEDIF(VLOOKUP(H26,$P$18:$Q$100,2,FALSE),TODAY(),"Y") -> 18 | I27: =DATEDIF(VLOOKUP(I26,$P$18:$Q$100,2,FALSE),TODAY(),"Y") -> 18 | ... L27: =DATEDIF(VLOOKUP(L26,$P$18:$Q$100,2,FALSE),TODAY(),"Y") -> 20 | N27: =AVERAGE(B27:M27) -> 19.909091 | P27: Österreicher | Q27: 38728
P28: Hosiner | Q28: 32643
A29: Stripfing | B29: Jusic | C29: Abdi | D29: Ilic | E29: Nisandzic | F29: Aleksa | G29: Wojnar | H29: Nnodim | I29: Ndukwe | J29: Mörth | K29: Ewemade | L29: Schablas | P29: Aleksa | Q29: 39197
B30: =DATEDIF(VLOOKUP(B29,$P$18:$Q$100,2,FALSE),TODAY(),"Y") -> 21 | C30: =DATEDIF(VLOOKUP(C29,$P$18:$Q$100,2,FALSE),TODAY(),"Y") -> 20 | D30: =DATEDIF(VLOOKUP(D29,$P$18:$Q$100,2,FALSE),TODAY(),"Y") -> 21 | E30: =DATEDIF(VLOOKUP(E29,$P$18:$Q$100,2,FALSE),TODAY(),"Y") -> 19 | F30: =DATEDIF(VLOOKUP(F29,$P$18:$Q$100,2,FALSE),TODAY(),"Y") -> 19 | G30: =DATEDIF(VLOOKUP(G29,$P$18:$Q$100,2,FALSE),TODAY(),"Y") -> 20 | H30: =DATEDIF(VLOOKUP(H29,$P$18:$Q$100,2,FALSE),TODAY(),"Y") -> 18 | I30: =DATEDIF(VLOOKUP(I29,$P$18:$Q$100,2,FALSE),TODAY(),"Y") -> 18 | ... L30: =DATEDIF(VLOOKUP(L29,$P$18:$Q$100,2,FALSE),TODAY(),"Y") -> 21 | N30: =AVERAGE(B30:M30) -> 19.636364 | P30: Fischer | Q30: 39031
P31: Lukic | Q31: 38851
A32: Austria | B32: Jusic | C32: Abdi | D32: Ilic | E32: Toifl | F32: Fischer | G32: Maybach | H32: Sawicki | I32: Höller | J32: Hosiner | K32: Ewemade | L32: Schablas | P32: Schablas | Q32: 38425
B33: =DATEDIF(VLOOKUP(B32,$P$18:$Q$100,2,FALSE),TODAY(),"Y") -> 21 | C33: =DATEDIF(VLOOKUP(C32,$P$18:$Q$100,2,FALSE),TODAY(),"Y") -> 20 | D33: =DATEDIF(VLOOKUP(D32,$P$18:$Q$100,2,FALSE),TODAY(),"Y") -> 21 | E33: =DATEDIF(VLOOKUP(E32,$P$18:$Q$100,2,FALSE),TODAY(),"Y") -> 21 | F33: =DATEDIF(VLOOKUP(F32,$P$18:$Q$100,2,FALSE),TODAY(),"Y") -> 19 | G33: =DATEDIF(VLOOKUP(G32,$P$18:$Q$100,2,FALSE),TODAY(),"Y") -> 18 | H33: =DATEDIF(VLOOKUP(H32,$P$18:$Q$100,2,FALSE),TODAY(),"Y") -> 20 | I33: =DATEDIF(VLOOKUP(I32,$P$18:$Q$100,2,FALSE),TODAY(),"Y") -> 18 | ... L33: =DATEDIF(VLOOKUP(L32,$P$18:$Q$100,2,FALSE),TODAY(),"Y") -> 21 | N33: =AVERAGE(B33:M33) -> 21.454545 | P33: Ilic | Q33: 38324
P34: Sawicki | Q34: 38653
A35: Liefering | B35: Jusic | C35: Abdi | D35: Lukic | E35: Toifl | F35: Fischer | G35: Mörth | H35: Wojnar | I35: Höller | J35: Hosiner | K35: Ewemade | L35: Schablas | P35: Zdichynec | Q35: 37284
B36: =DATEDIF(VLOOKUP(B35,$P$18:$Q$100,2,FALSE),TODAY(),"Y") -> 21 | C36: =DATEDIF(VLOOKUP(C35,$P$18:$Q$100,2,FALSE),TODAY(),"Y") -> 20 | D36: =DATEDIF(VLOOKUP(D35,$P$18:$Q$100,2,FALSE),TODAY(),"Y") -> 20 | E36: =DATEDIF(VLOOKUP(E35,$P$18:$Q$100,2,FALSE),TODAY(),"Y") -> 21 | F36: =DATEDIF(VLOOKUP(F35,$P$18:$Q$100,2,FALSE),TODAY(),"Y") -> 19 | G36: =DATEDIF(VLOOKUP(G35,$P$18:$Q$100,2,FALSE),TODAY(),"Y") -> 19 | H36: =DATEDIF(VLOOKUP(H35,$P$18:$Q$100,2,FALSE),TODAY(),"Y") -> 20 | I36: =DATEDIF(VLOOKUP(I35,$P$18:$Q$100,2,FALSE),TODAY(),"Y") -> 18 | ... L36: =DATEDIF(VLOOKUP(L35,$P$18:$Q$100,2,FALSE),TODAY(),"Y") -> 21 | N36: =AVERAGE(B36:M36) -> 21.454545 | P36: Deshishku | Q36: 39501
P37: Abdi | Q37: 38783
A38: FAC | B38: Jusic | C38: Ilic | D38: Lukic | E38: Toifl | F38: Fischer | G38: Mörth | H38: Maybach | I38: Pazourek | J38: Hosiner | K38: Nisandzic | L38: Schablas | P38: Ewemade | Q38: 38520
B39: =DATEDIF(VLOOKUP(B38,$P$18:$Q$100,2,FALSE),TODAY(),"Y") -> 21 | C39: =DATEDIF(VLOOKUP(C38,$P$18:$Q$100,2,FALSE),TODAY(),"Y") -> 21 | D39: =DATEDIF(VLOOKUP(D38,$P$18:$Q$100,2,FALSE),TODAY(),"Y") -> 20 | E39: =DATEDIF(VLOOKUP(E38,$P$18:$Q$100,2,FALSE),TODAY(),"Y") -> 21 | F39: =DATEDIF(VLOOKUP(F38,$P$18:$Q$100,2,FALSE),TODAY(),"Y") -> 19 | G39: =DATEDIF(VLOOKUP(G38,$P$18:$Q$100,2,FALSE),TODAY(),"Y") -> 19 | H39: =DATEDIF(VLOOKUP(H38,$P$18:$Q$100,2,FALSE),TODAY(),"Y") -> 18 | I39: =DATEDIF(VLOOKUP(I38,$P$18:$Q$100,2,FALSE),TODAY(),"Y") -> 21 | ... L39: =DATEDIF(VLOOKUP(L38,$P$18:$Q$100,2,FALSE),TODAY(),"Y") -> 21 | N39: =AVERAGE(B39:M39) -> 21.545455 | P39: Toifl | Q39: 38493
P40: Höller | Q40: 39427
A41: Bregenz | B41: Jusic | C41: Jankovic | D41: Lukic | E41: Toifl | F41: Fischer | G41: Mörth | H41: Roider | I41: Wojnar | J41: Hosiner | K41: Ewemade | L41: Österreicher | P41: Pazourek | Q41: 38387
B42: =DATEDIF(VLOOKUP(B41,$P$18:$Q$100,2,FALSE),TODAY(),"Y") -> 21 | C42: =DATEDIF(VLOOKUP(C41,$P$18:$Q$100,2,FALSE),TODAY(),"Y") -> 21 | D42: =DATEDIF(VLOOKUP(D41,$P$18:$Q$100,2,FALSE),TODAY(),"Y") -> 20 | E42: =DATEDIF(VLOOKUP(E41,$P$18:$Q$100,2,FALSE),TODAY(),"Y") -> 21 | F42: =DATEDIF(VLOOKUP(F41,$P$18:$Q$100,2,FALSE),TODAY(),"Y") -> 19 | G42: =DATEDIF(VLOOKUP(G41,$P$18:$Q$100,2,FALSE),TODAY(),"Y") -> 19 | H42: =DATEDIF(VLOOKUP(H41,$P$18:$Q$100,2,FALSE),TODAY(),"Y") -> 20 | I42: =DATEDIF(VLOOKUP(I41,$P$18:$Q$100,2,FALSE),TODAY(),"Y") -> 20 | ... L42: =DATEDIF(VLOOKUP(L41,$P$18:$Q$100,2,FALSE),TODAY(),"Y") -> 20 | N42: =AVERAGE(B42:M42) -> 21.636364 | P42: Roider | Q42: 38599
P43: Jankovic | Q43: 38364
A44: Kapfenberg | B44: Jusic | C44: Jankovic | D44: Nisandzic | E44: Toifl | F44: Fischer | G44: Mörth | H44: Roider | I44: Wojnar | J44: Hosiner | K44: Ewemade | L44: Österreicher | P44: Markovic | Q44: 39580
B45: =DATEDIF(VLOOKUP(B44,$P$18:$Q$100,2,FALSE),TODAY(),"Y") -> 21 | C45: =DATEDIF(VLOOKUP(C44,$P$18:$Q$100,2,FALSE),TODAY(),"Y") -> 21 | D45: =DATEDIF(VLOOKUP(D44,$P$18:$Q$100,2,FALSE),TODAY(),"Y") -> 19 | E45: =DATEDIF(VLOOKUP(E44,$P$18:$Q$100,2,FALSE),TODAY(),"Y") -> 21 | F45: =DATEDIF(VLOOKUP(F44,$P$18:$Q$100,2,FALSE),TODAY(),"Y") -> 19 | G45: =DATEDIF(VLOOKUP(G44,$P$18:$Q$100,2,FALSE),TODAY(),"Y") -> 19 | H45: =DATEDIF(VLOOKUP(H44,$P$18:$Q$100,2,FALSE),TODAY(),"Y") -> 20 | I45: =DATEDIF(VLOOKUP(I44,$P$18:$Q$100,2,FALSE),TODAY(),"Y") -> 20 | ... L45: =DATEDIF(VLOOKUP(L44,$P$18:$Q$100,2,FALSE),TODAY(),"Y") -> 20 | N45: =AVERAGE(B45:M45) -> 21.545455 | P45: Stöger | Q45: 38999
...

Sheet WAC
N1: =AVERAGE(N3:N99) -> 20.98951
A2: St. Anna | B2: Skubl | C2: Six | D2: Schweiger | E2: Romanyuk B. | F2: Romanyuk K. | G2: Skyriotis | H2: Hajdini | I2: Ademi | J2: Agbevor | K2: Krause | L2: Durakovic
B3: =DATEDIF(VLOOKUP(B2,$P$18:$Q$100,2,FALSE),TODAY(),"Y") -> 24 | C3: =DATEDIF(VLOOKUP(C2,$P$18:$Q$100,2,FALSE),TODAY(),"Y") -> 19 | D3: =DATEDIF(VLOOKUP(D2,$P$18:$Q$100,2,FALSE),TODAY(),"Y") -> 20 | E3: =DATEDIF(VLOOKUP(E2,$P$18:$Q$100,2,FALSE),TODAY(),"Y") -> 25 | F3: =DATEDIF(VLOOKUP(F2,$P$18:$Q$100,2,FALSE),TODAY(),"Y") -> 25 | G3: =DATEDIF(VLOOKUP(G2,$P$18:$Q$100,2,FALSE),TODAY(),"Y") -> 20 | H3: =DATEDIF(VLOOKUP(H2,$P$18:$Q$100,2,FALSE),TODAY(),"Y") -> 19 | I3: =DATEDIF(VLOOKUP(I2,$P$18:$Q$100,2,FALSE),TODAY(),"Y") -> 20 | ... L3: =DATEDIF(VLOOKUP(L2,$P$18:$Q$100,2,FALSE),TODAY(),"Y") -> 19 | N3: =AVERAGE(B3:M3) -> 21.272727
A5: Treibach | B5: Skubl | C5: Six | D5: Schweiger | E5: Romanyuk B. | F5: Romanyuk K. | G5: Skyriotis | H5: Fritzer | I5: Ademi | J5: Agbevor | K5: Krause | L5: Durakovic
